Workbook

Sheet Combined_Data
B1: Data (in Megabytes) | O1: Talktime (in Minutes) | AB1: Plan | AC1: Billing (in Euros)
A2: Customer_ID | B2: January_Data | C2: February_Data | D2: March_Data | E2: April_Data | F2: May_Data | G2: June_Data | H2: July_Data | I2: August_Data | J2: September_Data | K2: October_Data | L2: November_Data | M2: December_Data | N2: Total_Data_Usage | O2: January_Talktime | P2: February_Talktime | Q2: March_Talktime | R2: April_Talktime | S2: May_Talktime | T2: June_Talktime | U2: July_Talktime | V2: August_Talktime | W2: September_Talktime | X2: October_Talktime | Y2: November_Talktime | Z2: December_Talktime | AA2: Total_Talktime | AB2: Plan | AC2: January | AD2: February | AE2: March | AF2: April | AG2: May | AH2: June | AI2: July | AJ2: August | AK2: September | AL2: October | AM2: November | AN2: December | AO2: Total billing amount
A3: SUB-729143503 | B3: 28053.56 | C3: 2895.5485 | D3: 1351.6937 | E3: 3756.5219 | F3: 223.77361 | G3: 4012.203 | H3: 9166.6329 | I3: 5241.1959 | J3: 1596.4707 | K3: 961.4416 | L3: 0 | M3: 456.79371 | N3: =SUM(B3:M3) -> 57715.836 | O3: 0 | P3: 6.8243443 | Q3: 1.8348294 | R3: 0.13054242 | S3: 1.2363395 | T3: 5.2688933 | U3: 12.071899 | V3: 0 | W3: 9.526224 | X3: 9.9057137 | Y3: 10.55318 | Z3: 3.5335249 | AA3: =SUM(O3:Z3) -> 60.885491 | AB3: Reduced rate | AC3: 290.53 | AD3: 39.3 | AE3: 23.61 | AF3: 47.61 | AG3: 12.33 | AH3: 50.42 | AI3: 102.31 | AJ3: 62.41 | AK3: 26.46 | AL3: 20.11 | AM3: 10.54 | AN3: 14.76 | AO3: =SUM(AC3:AN3) -> 700.39
A4: SUB-327259441 | B4: 27981.652 | C4: 417.81517 | D4: 852.48705 | E4: 635.07388 | F4: 663.3152 | G4: 4986.3074 | H4: 1854.487 | I4: 6695.5891 | J4: 1891.9995 | K4: 887.893 | L4: 743.67274 | M4: 2697.434 | N4: =SUM(B4:M4) -> 50307.726 | O4: 3.0272902 | P4: 0 | Q4: 3.1933096 | R4: 13.726478 | S4: 2.7197324 | T4: 0.56202084 | U4: 1.6899206 | V4: 0.95496648 | W4: 2.2011679 | X4: 0.22231461 | Y4: 6.2190388 | Z4: 1.1186908 | AA4: =SUM(O4:Z4) -> 35.63493 | AB4: Reduced rate | AC4: 290.01 | AD4: 14.17 | AE4: 18.72 | AF4: 17.05 | AG4: 16.78 | AH4: 59.91 | AI4: 28.64 | AJ4: 77 | AK4: 29.06 | AL4: 18.92 | AM4: 17.78 | AN4: 37.07 | AO4: =SUM(AC4:AN4) -> 625.11
A5: SUB-720199369 | B5: 24077.595 | C5: 2040.3707 | D5: 697.99085 | E5: 2976.9148 | F5: 3284.5485 | G5: 0 | H5: 882.75571 | I5: 5062.1182 | J5: 1429.7181 | K5: 471.10911 | L5: 2549.1186 | M5: 347.76244 | N5: =SUM(B5:M5) -> 43820.002 | O5: 3.6953248 | P5: 5.7223518 | Q5: 1.9044145 | R5: 3.6303551 | S5: 2.6919952 | T5: 2.7536809 | U5: 7.5746851 | V5: 0 | W5: 1.6038991 | X5: 8.9788221 | Y5: 0.68691512 | Z5: 4.9413438 | AA5: =SUM(O5:Z5) -> 44.183788 | AB5: Reduced rate | AC5: 250.97 | AD5: 30.7 | AE5: 17.07 | AF5: 39.96 | AG5: 42.99 | AH5: 10.14 | AI5: 19.22 | AJ5: 60.62 | AK5: 24.39 | AL5: 15.16 | AM5: 35.54 | AN5: 13.72 | AO5: =SUM(AC5:AN5) -> 560.48
A6: SUB-115774364 | B6: 23074.756 | C6: 2785.5024 | D6: 284.71385 | E6: 3283.7711 | F6: 7459.8083 | G6: 3168.5675 | H6: 1907.4737 | I6: 339.31373 | J6: 2228.1186 | K6: 2686.797 | L6: 1170.1683 | M6: 7622.4986 | N6: =SUM(B6:M6) -> 56011.489 | O6: 1.0159856 | P6: 0.15372142 | Q6: 4.6900202 | R6: 4.5204292 | S6: 2.0791638 | T6: 6.6181137 | U6: 7.6565992 | V6: 5.3556575 | W6: 0 | X6: 3.3847081 | Y6: 3.4338634 | Z6: 4.6570532 | AA6: =SUM(O6:Z6) -> 43.565315 | AB6: Reduced rate | AC6: 240.84 | AD6: 37.9 | AE6: 13.09 | AF6: 43.08 | AG6: 84.74 | AH6: 42.03 | AI6: 29.47 | AJ6: 13.69 | AK6: 32.28 | AL6: 37.06 | AM6: 21.9 | AN6: 86.47 | AO6: =SUM(AC6:AN6) -> 682.55
A7: SUB-687511952 | B7: 22979.493 | C7: 2122.315 | D7: 876.83085 | E7: 5628.9233 | F7: 0 | G7: 1865.4922 | H7: 757.8359 | I7: 9671.7792 | J7: 2997.9954 | K7: 7828.6764 | L7: 1929.7365 | M7: 1642.5122 | N7: =SUM(B7:M7) -> 58301.59 | O7: 0 | P7: 0.28491236 | Q7: 2.3988806 | R7: 1.1966899 | S7: 1.2630293 | T7: 3.6460268 | U7: 1.5113669 | V7: 1.7826923 | W7: 6.1010391 | X7: 6.4017515 | Y7: 3.0686748 | Z7: 8.3819532 | AA7: =SUM(O7:Z7) -> 36.037017 | AB7: Reduced rate | AC7: 239.79 | AD7: 31.27 | AE7: 18.91 | AF7: 66.38 | AG7: 10.09 | AH7: 28.85 | AI7: 17.67 | AJ7: 106.81 | AK7: 40.32 | AL7: 88.63 | AM7: 29.49 | AN7: 26.87 | AO7: =SUM(AC7:AN7) -> 705.08
A8: SUB-884111294 | B8: 21172.886 | C8: 1523.6876 | D8: 1485.3058 | E8: 4193.1236 | F8: 1956.6123 | G8: 1901.2535 | H8: 3119.8269 | I8: 2239.8238 | J8: 5877.3904 | K8: 1648.9666 | L8: 9274.7754 | M8: 6059.3035 | N8: =SUM(B8:M8) -> 60452.956 | O8: 3.480402 | P8: 2.7555623 | Q8: 8.512322 | R8: 8.4869033 | S8: 0 | T8: 7.3523678 | U8: 2.5343937 | V8: 18.001429 | W8: 1.1814809 | X8: 18.746402 | Y8: 4.5426855 | Z8: 1.2377769 | AA8: =SUM(O8:Z8) -> 76.831726 | AB8: Reduced rate | AC8: 221.92 | AD8: 25.38 | AE8: 25.3 | AF8: 52.38 | AG8: 29.56 | AH8: 29.41 | AI8: 41.34 | AJ8: 33.34 | AK8: 68.87 | AL8: 27.43 | AM8: 102.99 | AN8: 70.69 | AO8: =SUM(AC8:AN8) -> 728.61
A9: SUB-754009185 | B9: 17677.832 | C9: 4761.3302 | D9: 3058.4981 | E9: 9399.811 | F9: 8675.879 | G9: 5734.8376 | H9: 3587.2216 | I9: 3564.4166 | J9: 1240.7474 | K9: 155.30631 | L9: 2065.3096 | M9: 2312.6221 | N9: =SUM(B9:M9) -> 62233.812 | O9: 4.6764258 | P9: 3.7891882 | Q9: 4.3049763 | R9: 5.2743849 | S9: 3.8110392 | T9: 0.29090471 | U9: 2.0522614 | V9: 4.2704145 | W9: 0.45728292 | X9: 1.6975736 | Y9: 1.5591213 | Z9: 2.8046566 | AA9: =SUM(O9:Z9) -> 34.988229 | AB9: Reduced rate | AC9: 187.02 | AD9: 57.81 | AE9: 40.83 | AF9: 104.29 | AG9: 96.95 | AH9: 67.39 | AI9: 46.02 | AJ9: 45.89 | AK9: 22.45 | AL9: 11.65 | AM9: 30.75 | AN9: 33.27 | AO9: =SUM(AC9:AN9) -> 744.32
A10: SUB-907933772 | B10: 17562.336 | C10: 1588.6695 | D10: 1873.9256 | E10: 12191.94 | F10: 3104.8013 | G10: 1559.3144 | H10: 4198.5673 | I10: 255.28364 | J10: 1706.0694 | K10: 506.10295 | L10: 317.99446 | M10: 0 | N10: =SUM(B10:M10) -> 44865.004 | O10: 0 | P10: 0.62814977 | Q10: 3.5003327 | R10: 3.3931231 | S10: 9.6599002 | T10: 2.2831001 | U10: 11.323904 | V10: 0.77391993 | W10: 0 | X10: 0 | Y10: 0 | Z10: 2.4815975 | AA10: =SUM(O10:Z10) -> 34.044027 | AB10: Reduced rate | AC10: 185.62 | AD10: 25.93 | AE10: 28.93 | AF10: 132.11 | AG10: 41.54 | AH10: 25.74 | AI10: 52.58 | AJ10: 12.6 | AK10: 27.06 | AL10: 15.06 | AM10: 13.17 | AN10: 10.14 | AO10: =SUM(AC10:AN10) -> 570.48
A11: SUB-219686190 | B11: 17310.819 | C11: 1600.9242 | D11: 4071.8053 | E11: 808.60022 | F11: 208.4777 | G11: 6817.1882 | H11: 1511.4908 | I11: 1614.1089 | J11: 1723.2336 | K11: 11608.721 | L11: 0 | M11: 5663.6196 | N11: =SUM(B11:M11) -> 52938.988 | O11: 0.16695997 | P11: 1.3625016 | Q11: 5.6891728 | R11: 5.6100635 | S11: 1.8632851 | T11: 0 | U11: 2.7344741 | V11: 2.7288639 | W11: 10.096708 | X11: 4.570316 | Y11: 0.73125341 | Z11: 3.9632105 | AA11: =SUM(O11:Z11) -> 39.516809 | AB11: Reduced rate | AC11: 183.15 | AD11: 26.1 | AE11: 51.01 | AF11: 18.38 | AG11: 12.18 | AH11: 78.17 | AI11: 25.26 | AJ11: 26.29 | AK11: 27.78 | AL11: 126.33 | AM11: 10.04 | AN11: 66.83 | AO11: =SUM(AC11:AN11) -> 651.52
A12: SUB-275406642 | B12: 16752.503 | C12: 6126.3628 | D12: 2972.6152 | E12: 4473.5263 | F12: 5774.8251 | G12: 2388.7042 | H12: 6406.1825 | I12: 1414.0145 | J12: 1243.7208 | K12: 2317.0722 | L12: 4556.8202 | M12: 4306.3377 | N12: =SUM(B12:M12) -> 58732.684 | O12: 6.9119753 | P12: 0.18325476 | Q12: 5.0499693 | R12: 3.018949 | S12: 11.830532 | T12: 0.1598578 | U12: 2.7107988 | V12: 9.711794 | W12: 0.44653473 | X12: 12.236804 | Y12: 3.7763513 | Z12: 1.7315306 | AA12: =SUM(O12:Z12) -> 57.768352 | AB12: Reduced rate | AC12: 177.87 | AD12: 71.31 | AE12: 40.02 | AF12: 54.93 | AG12: 68.34 | AH12: 33.93 | AI12: 74.21 | AJ12: 24.64 | AK12: 22.48 | AL12: 33.82 | AM12: 55.76 | AN12: 53.16 | AO12: =SUM(AC12:AN12) -> 710.47
A13: SUB-475178203 | B13: 16234.974 | C13: 3934.7617 | D13: 5727.4151 | E13: 0 | F13: 7942.5962 | G13: 11273.978 | H13: 2245.1036 | I13: 5506.8814 | J13: 2619.9452 | K13: 631.70776 | L13: 6969.3265 | M13: 3442.1968 | N13: =SUM(B13:M13) -> 66528.886 | O13: 0.10338663 | P13: 3.6698164 | Q13: 0 | R13: 10.17963 | S13: 6.6749883 | T13: 5.0695154 | U13: 1.0149742 | V13: 7.4529844 | W13: 7.397938 | X13: 5.9770251 | Y13: 1.926056 | Z13: 4.0583869 | AA13: =SUM(O13:Z13) -> 53.524702 | AB13: Reduced rate | AC13: 172.39 | AD13: 49.54 | AE13: 67.27 | AF13: 10.54 | AG13: 89.77 | AH13: 123.03 | AI13: 32.55 | AJ13: 65.46 | AK13: 36.59 | AL13: 16.61 | AM13: 79.79 | AN13: 44.67 | AO13: =SUM(AC13:AN13) -> 788.21
A14: SUB-384428935 | B14: 16201.279 | C14: 1976.3677 | D14: 1334.0698 | E14: 6880.8346 | F14: 2098.5512 | G14: 1613.6047 | H14: 1941.8694 | I14: 3510.1076 | J14: 0 | K14: 1530.7356 | L14: 2422.2141 | M14: 1134.3007 | N14: =SUM(B14:M14) -> 40643.934 | O14: 2.2438026 | P14: 20.086245 | Q14: 0 | R14: 2.9771223 | S14: 11.89283 | T14: 0.27558812 | U14: 14.22914 | V14: 11.30351 | W14: 8.9568708 | X14: 2.5598834 | Y14: 5.6794312 | Z14: 6.6390676 | AA14: =SUM(O14:Z14) -> 86.843491 | AB14: Reduced rate | AC14: 172.16 | AD14: 30.81 | AE14: 23.34 | AF14: 78.95 | AG14: 31.58 | AH14: 26.18 | AI14: 30.16 | AJ14: 45.7 | AK14: 10.44 | AL14: 25.45 | AM14: 34.52 | AN14: 21.69 | AO14: =SUM(AC14:AN14) -> 530.98
... A893: SUB-794177654 | B893: 9.9468182 | C893: 3853.098 | D893: 2169.3201 | E893: 3469.7822 | F893: 4577.7392 | G893: 4563.6135 | H893: 3504.2403 | I893: 3348.378 | J893: 787.56729 | K893: 886.27349 | L893: 3231.5868 | M893: 2240.2039 | N893: =SUM(B893:M893) -> 32641.75 | O893: 2.2824462 | P893: 2.7843054 | Q893: 3.4749852 | R893: 3.2232285 | S893: 2.3887401 | T893: 6.5501937 | U893: 4.0512609 | V893: 0 | W893: 2.0447171 | X893: 5.6797415 | Y893: 2.6602769 | Z893: 3.6138055 | AA893: =SUM(O893:Z893) -> 38.753701 | AB893: Pay-as-you-go | AC893: 0.47 | AD893: 77.35 | AE893: 43.76 | AF893: 69.76 | AG893: 91.83 | AH893: 91.91 | AI893: 70.55 | AJ893: 66.98 | AK893: 16.03 | AL893: 18.28 | AM893: 64.91 | AN893: 45.18 | AO893: =SUM(AC893:AN893) -> 657.01
A894: SUB-928511911 | B894: 0 | C894: 12943.116 | D894: 6297.5226 | E894: 0 | F894: 28266.985 | G894: 2921.4545 | H894: 6336.0007 | I894: 216.28226 | J894: 1422.9196 | K894: 4797.8424 | L894: 286.28697 | M894: 2230.0758 | N894: =SUM(B894:M894) -> 65718.486 | O894: 0 | P894: 3.143746 | Q894: 10.909133 | R894: 4.6205672 | S894: 4.4109608 | T894: 3.5561012 | U894: 1.3723442 | V894: 3.6591779 | W894: 4.0311417 | X894: 1.8237247 | Y894: 1.6657105 | Z894: 2.318 | AA894: =SUM(O894:Z894) -> 41.510607 | AB894: Pay-as-you-go | AD894: 259.24 | AE894: 126.95 | AF894: 0.45 | AG894: 565.79 | AH894: 58.8 | AI894: 126.92 | AJ894: 4.7 | AK894: 28.91 | AL894: 96.14 | AM894: 5.92 | AN894: 44.89 | AO894: =SUM(AC894:AN894) -> 1318.71
A895: SUB-414114481 | B895: 0 | C895: 8454.2086 | D895: 10680.127 | E895: 16875.697 | F895: 6880.6843 | G895: 611.32179 | H895: 4752.2527 | I895: 516.2456 | J895: 7758.3414 | K895: 1042.6837 | L895: 517.05686 | M895: 8528.1632 | N895: =SUM(B895:M895) -> 66616.782 | O895: 2.9461809 | P895: 16.467007 | Q895: 4.0925789 | R895: 0.47543171 | S895: 0.55776133 | T895: 2.6805405 | U895: 0 | V895: 0 | W895: 1.5391586 | X895: 2.926375 | Y895: 2.4096702 | Z895: 1.1639022 | AA895: =SUM(O895:Z895) -> 35.258606 | AB895: Pay-as-you-go | AC895: 0.27 | AD895: 170.63 | AE895: 214.07 | AF895: 337.61 | AG895: 137.71 | AH895: 12.51 | AI895: 95.06 | AJ895: 10.34 | AK895: 155.36 | AL895: 21.13 | AM895: 10.63 | AN895: 170.76 | AO895: =SUM(AC895:AN895) -> 1336.08
A896: SUB-996400695 | B896: 0 | C896: 6783.8768 | D896: 1702.1 | E896: 1356.2098 | F896: 3224.3312 | G896: 2121.5025 | H896: 3375.4283 | I896: 3243.749 | J896: 4071.1388 | K896: 6329.0776 | L896: 886.36755 | M896: 1918.468 | N896: =SUM(B896:M896) -> 35012.25 | O896: 0 | P896: 0.85333558 | Q896: 14.725982 | R896: 0.96556171 | S896: 4.0969138 | T896: 0.93532242 | U896: 6.2974214 | V896: 0 | W896: 14.425496 | X896: 1.3316665 | Y896: 0 | Z896: 0 | AA896: =SUM(O896:Z896) -> 43.631699 | AB896: Pay-as-you-go | AD896: 135.77 | AE896: 35.41 | AF896: 27.23 | AG896: 64.95 | AH896: 42.53 | AI896: 68.15 | AJ896: 64.88 | AK896: 82.79 | AL896: 126.78 | AM896: 17.74 | AN896: 38.38 | AO896: =SUM(AC896:AN896) -> 704.61
A897: SUB-137805061 | B897: 0 | C897: 5484.7744 | D897: 0 | E897: 1240.4971 | F897: 3882.5124 | G897: 3913.9764 | H897: 5068.3519 | I897: 2804.4772 | J897: 2661.8752 | K897: 8753.3647 | L897: 2345.7654 | M897: 2.2910935 | N897: =SUM(B897:M897) -> 36157.886 | O897: 0 | P897: 0.3594828 | Q897: 10.165985 | R897: 1.0537743 | S897: 3.8019961 | T897: 5.2162518 | U897: 0.48317986 | V897: 15.445314 | W897: 13.465932 | X897: 2.6964304 | Y897: 3.317922 | Z897: 0.34897139 | AA897: =SUM(O897:Z897) -> 56.35524 | AB897: Pay-as-you-go | AD897: 109.79 | AE897: 0.99 | AF897: 25 | AG897: 78.02 | AH897: 78.82 | AI897: 101.47 | AJ897: 57.54 | AK897: 54.5 | AL897: 175.35 | AM897: 47.28 | AN897: 0.15 | AO897: =SUM(AC897:AN897) -> 728.91
A898: SUB-474945743 | B898: 0 | C898: 5079.4745 | D898: 3051.7562 | E898: 4641.0843 | F898: 386.82587 | G898: 11215.752 | H898: 0 | I898: 1680.3037 | J898: 3298.6346 | K898: 0 | L898: 332.59172 | M898: 527.06218 | N898: =SUM(B898:M898) -> 30213.485 | O898: 6.0295045 | P898: 1.9204556 | Q898: 3.9256962 | R898: 6.2211833 | S898: 0.26186595 | T898: 13.566048 | U898: 7.3645143 | V898: 2.2805143 | W898: 1.5158335 | X898: 0 | Y898: 1.7242916 | Z898: 7.1470572 | AA898: =SUM(O898:Z898) -> 51.956964 | AB898: Pay-as-you-go | AC898: 0.63 | AD898: 101.78 | AE898: 61.4 | AF898: 93.47 | AG898: 7.83 | AH898: 225.58 | AI898: 0.72 | AJ898: 33.89 | AK898: 66.16 | AL898: 0 | AM898: 6.84 | AN898: 11.28 | AO898: =SUM(AC898:AN898) -> 609.58
A899: SUB-320112847 | B899: 0 | C899: 5014.25 | D899: 739.38302 | E899: 3380.8393 | F899: 718.5235 | G899: 2377.1628 | H899: 6412.137 | I899: 5459.3947 | J899: 908.63328 | K899: 2807.3975 | L899: 2701.4436 | M899: 877.34389 | N899: =SUM(B899:M899) -> 31396.509 | O899: 0.33632751 | P899: 0 | Q899: 2.8809274 | R899: 4.4286643 | S899: 4.0173057 | T899: 0 | U899: 13.658446 | V899: 0 | W899: 1.4127249 | X899: 0 | Y899: 3.1925685 | Z899: 11.94017 | AA899: =SUM(O899:Z899) -> 41.867134 | AB899: Pay-as-you-go | AC899: 0.09 | AD899: 100.3 | AE899: 15.07 | AF899: 68.07 | AG899: 14.83 | AH899: 47.56 | AI899: 129.52 | AJ899: 109.2 | AK899: 18.36 | AL899: 56.16 | AM899: 54.4 | AN899: 18.64 | AO899: =SUM(AC899:AN899) -> 632.2
A900: SUB-309284306 | B900: 0 | C900: 4804.5749 | D900: 2451.5004 | E900: 0 | F900: 5312.3956 | G900: 4973.7967 | H900: 1409.7628 | I900: 531.20554 | J900: 1428.6927 | K900: 2789.2733 | L900: 7452.1114 | M900: 1635.8805 | N900: =SUM(B900:M900) -> 32789.194 | O900: 3.5190982 | P900: 7.8010408 | Q900: 2.5400861 | R900: 2.4616911 | S900: 4.4692417 | T900: 0.81136147 | U900: 2.9430812 | V900: 6.4497894 | W900: 2.0919546 | X900: 4.9004954 | Y900: 3.2855948 | Z900: 0 | AA900: =SUM(O900:Z900) -> 41.273435 | AB900: Pay-as-you-go | AC900: 0.36 | AD900: 96.82 | AE900: 49.31 | AF900: 0.27 | AG900: 106.71 | AH900: 99.57 | AI900: 28.47 | AJ900: 11.27 | AK900: 28.85 | AL900: 56.25 | AM900: 149.42 | AN900: 32.72 | AO900: =SUM(AC900:AN900) -> 660.02
A901: SUB-314510883 | B901: 0 | C901: 4620.9847 | D901: 1886.8344 | E901: 0 | F901: 1444.3624 | G901: 0 | H901: 5514.5869 | I901: 4785.3439 | J901: 7557.7599 | K901: 2455.76 | L901: 809.99158 | M901: 352.25 | N901: =SUM(B901:M901) -> 29427.874 | O901: 1.3009787 | P901: 3.1672884 | Q901: 4.1297905 | R901: 2.6446201 | S901: 3.3277668 | T901: 0 | U901: 2.3122589 | V901: 1.5170059 | W901: 12.619266 | X901: 7.1188983 | Y901: 12.892263 | Z901: 0 | AA901: =SUM(O901:Z901) -> 51.030138 | AB901: Pay-as-you-go | AC901: 0.18 | AD901: 92.78 | AE901: 38.19 | AF901: 0.27 | AG901: 29.26 | AH901: 0 | AI901: 110.57 | AJ901: 95.9 | AK901: 152.33 | AL901: 49.84 | AM901: 17.37 | AN901: 7.06 | AO901: =SUM(AC901:AN901) -> 593.75
A902: SUB-890910481 | B902: 0 | C902: 4605.8996 | D902: 3328.3965 | E902: 3228.9678 | F902: 1212.7425 | G902: 227.11129 | H902: 5438.5608 | I902: 7126.2902 | J902: 2028.2079 | K902: 926.65434 | L902: 0 | M902: 4875.7541 | N902: =SUM(B902:M902) -> 32998.585 | O902: 6.2240737 | P902: 5.1990476 | Q902: 0 | R902: 3.7238477 | S902: 2.0036781 | T902: 0 | U902: 8.2255529 | V902: 0 | W902: 1.0910262 | X902: 11.478312 | Y902: 1.5648237 | Z902: 16.801943 | AA902: =SUM(O902:Z902) -> 56.312305 | AB902: Pay-as-you-go | AC902: 0.63 | AD902: 92.66 | AE902: 66.58 | AF902: 64.94 | AG902: 24.53 | AH902: 4.56 | AI902: 109.59 | AJ902: 142.54 | AK902: 40.76 | AL902: 19.62 | AM902: 0.18 | AN902: 99.05 | AO902: =SUM(AC902:AN902) -> 665.64
A903: SUB-122771504 | B903: 0 | C903: 3664.2394 | D903: 8411.2078 | E903: 454.06967 | F903: 1633.6899 | G903: 5542.6689 | H903: 1794.0526 | I903: 0 | J903: 1216.3224 | K903: 1436.7165 | L903: 7041.9234 | M903: 2812.2744 | N903: =SUM(B903:M903) -> 34007.165 | O903: 8.4321304 | P903: 2.1134551 | Q903: 0 | R903: 1.224747 | S903: 0.026622636 | T903: 4.0980804 | U903: 1.1773012 | V903: 0 | W903: 3.4528805 | X903: 0.85734524 | Y903: 2.5651186 | Z903: 3.4059173 | AA903: =SUM(O903:Z903) -> 27.353598 | AB903: Pay-as-you-go | AC903: 0.81 | AD903: 73.57 | AE903: 168.24 | AF903: 9.28 | AG903: 32.77 | AH903: 111.31 | AI903: 36.08 | AJ903: 0 | AK903: 24.7 | AL903: 28.83 | AM903: 141.11 | AN903: 56.62 | AO903: =SUM(AC903:AN903) -> 683.32
A904: SUB-907081959 | B904: 0 | C904: 3662.5494 | D904: 3229.8721 | E904: 7818.6524 | F904: 50.22897 | G904: 1620.0292 | H904: 602.43523 | I904: 11646.178 | J904: 1330.8063 | K904: 299.56011 | L904: 2454.4619 | M904: 2452.6881 | N904: =SUM(B904:M904) -> 35167.462 | O904: 8.4747469 | P904: 0.9824248 | Q904: 4.1397984 | R904: 1.9751674 | S904: 0 | T904: 9.1914476 | U904: 7.867708 | V904: 4.6662279 | W904: 8.3235229 | X904: 8.951715 | Y904: 4.1383622 | Z904: 5.7404462 | AA904: =SUM(O904:Z904) -> 64.451567 | AB904: Pay-as-you-go | AC904: 0.81 | AD904: 73.35 | AE904: 65.05 | AF904: 156.56 | AG904: 1.02 | AH904: 33.32 | AI904: 12.78 | AJ904: 233.39 | AK904: 27.43 | AL904: 6.81 | AM904: 49.55 | AN904: 49.6 | AO904: =SUM(AC904:AN904) -> 709.67
A905: SUB-207733458 | B905: 0 | C905: 3422.9037 | D905: 3194.2143 | E905: 925.21193 | F905: 6027.4984 | G905: 147.44332 | H905: 5406.6288 | I905: 793.94908 | J905: 4140.8474 | K905: 993.63492 | L905: 599.49863 | M905: 4854.5732 | N905: =SUM(B905:M905) -> 30506.404 | O905: 3.1652242 | P905: 6.637187 | Q905: 0.31920959 | R905: 4.0460599 | S905: 4.3977899 | T905: 0 | U905: 3.6307329 | V905: 5.7180518 | W905: 2.586169 | X905: 0 | Y905: 0 | Z905: 1.8402756 | AA905: =SUM(O905:Z905) -> 32.3407 | AB905: Pay-as-you-go | AC905: 0.36 | AD905: 69.09 | AE905: 63.99 | AF905: 18.97 | AG905: 121.01 | AH905: 2.96 | AI905: 108.5 | AJ905: 16.42 | AK905: 83.09 | AL905: 19.88 | AM905: 12 | AN905: 97.28 | AO905: =SUM(AC905:AN905) -> 613.55
A906: SUB-742447206 | B906: 0 | C906: 3354.923 | D906: 2162.1738 | E906: 5881.6181 | F906: 3083.3459 | G906: 6987.3869 | H906: 675.44656 | I906: 3188.7628 | J906: 953.43203 | K906: 1651.894 | L906: 7813.6043 | M906: 1368.259 | N906: =SUM(B906:M906) -> 37120.846 | O906: 6.8847197 | P906: 10.097849 | Q906: 2.0008783 | R906: 1.7907601 | S906: 2.4606165 | T906: 8.2887288 | U906: 0.7105894 | V906: 0.59352954 | W906: 7.1342775 | X906: 0.44956576 | Y906: 4.1726052 | Z906: 0.69299067 | AA906: =SUM(O906:Z906) -> 45.277111 | AB906: Pay-as-you-go | AC906: 0.63 | AD906: 68.09 | AE906: 43.53 | AF906: 117.82 | AG906: 61.95 | AH906: 140.57 | AI906: 13.61 | AJ906: 63.87 | AK906: 19.8 | AL906: 33.13 | AM906: 156.73 | AN906: 27.47 | AO906: =SUM(AC906:AN906) -> 747.2
A907: SUB-425606111 | B907: 0 | C907: 3178.4601 | D907: 8157.9796 | E907: 489.22732 | F907: 2367.0085 | G907: 5264.7096 | H907: 636.72291 | I907: 0 | J907: 2523.7437 | K907: 5092.2597 | L907: 169.45737 | M907: 6130.407 | N907: =SUM(B907:M907) -> 34009.976 | O907: 4.4804098 | P907: 6.9490902 | Q907: 8.8145112 | R907: 6.3976384 | S907: 1.093635 | T907: 2.4004427 | U907: 2.0596671 | V907: 4.5974445 | W907: 1.9828325 | X907: 3.2631922 | Y907: 1.1317575 | Z907: 0.6316402 | AA907: =SUM(O907:Z907) -> 43.802261 | AB907: Pay-as-you-go | AC907: 0.45 | AD907: 64.21 | AE907: 163.97 | AF907: 10.43 | AG907: 47.54 | AH907: 105.57 | AI907: 13.01 | AJ907: 0.45 | AK907: 50.66 | AL907: 102.22 | AM907: 3.58 | AN907: 122.71 | AO907: =SUM(AC907:AN907) -> 684.8
A908: SUB-545952317 | B908: 0 | C908: 2740.1332 | D908: 2012.966 | E908: 1934.6194 | F908: 5212.4989 | G908: 1487.2239 | H908: 7323.9396 | I908: 0 | J908: 1773.8144 | K908: 4350.4284 | L908: 2431.9344 | M908: 0 | N908: =SUM(B908:M908) -> 29267.558 | O908: 9.0067892 | P908: 6.1576562 | Q908: 6.5630083 | R908: 4.3489986 | S908: 0.9215398 | T908: 4.7684233 | U908: 0.53045653 | V908: 3.6569762 | W908: 0 | X908: 6.264829 | Y908: 0 | Z908: 10.19993 | AA908: =SUM(O908:Z908) -> 52.418608 | AB908: Pay-as-you-go | AC908: 0.9 | AD908: 55.45 | AE908: 40.89 | AF908: 39.15 | AG908: 104.35 | AH908: 30.21 | AI908: 146.57 | AJ908: 0.36 | AK908: 35.48 | AL908: 87.65 | AM908: 48.64 | AN908: 0.99 | AO908: =SUM(AC908:AN908) -> 590.64
A909: SUB-921245657 | B909: 0 | C909: 2500.5925 | D909: 1211.2454 | E909: 2888.3056 | F909: 0 | G909: 3454.4579 | H909: 4242.7551 | I909: 1785.7606 | J909: 1281.8911 | K909: 0 | L909: 381.16362 | M909: 2290.5001 | N909: =SUM(B909:M909) -> 20036.672 | O909: 11.137581 | P909: 1.9751824 | Q909: 14.763221 | R909: 1.747871 | S909: 11.010165 | T909: 0.26696745 | U909: 6.5584539 | V909: 2.1556627 | W909: 3.3403359 | X909: 0.79504318 | Y909: 5.3994002 | Z909: 0 | AA909: =SUM(O909:Z909) -> 59.149883 | AB909: Pay-as-you-go | AC909: 1.08 | AD909: 50.2 | AE909: 25.59 | AF909: 57.96 | AG909: 1.08 | AH909: 69.19 | AI909: 85.49 | AJ909: 35.99 | AK909: 26 | AL909: 0.09 | AM909: 8.18 | AN909: 45.82 | AO909: =SUM(AC909:AN909) -> 406.67
... A949: SUB-984807958 | B949: 0 | C949: 5769.4768 | D949: 5927.6482 | E949: 4890.5559 | F949: 382.82538 | G949: 4217.6234 | H949: 1305.2195 | I949: 2043.3128 | J949: 754.4429 | K949: 9398.8742 | L949: 942.14411 | M949: 2971.3993 | N949: =SUM(B949:M949) -> 38603.523 | O949: 1.4061369 | P949: 2.4444008 | Q949: 6.1520597 | R949: 9.2948668 | S949: 9.0367289 | T949: 5.3916786 | U949: 8.8367753 | V949: 1.9468334 | W949: 0.35880581 | X949: 1.4556245 | Y949: 0.90654344 | Z949: 0.73464789 | AA949: =SUM(O949:Z949) -> 47.965102 | AB949: Reduced rate | AC949: 10.09 | AD949: 67.84 | AE949: 69.62 | AF949: 59.4 | AG949: 14.32 | AH949: 52.47 | AI949: 23.5 | AJ949: 30.53 | AK949: 17.59 | AL949: 104.08 | AM949: 19.47 | AN949: 39.76 | AO949: =SUM(AC949:AN949) -> 508.67
A950: SUB-538425944 | C950: 5504.66 | D950: 2570.6549 | E950: 3231.9962 | F950: 980.81565 | G950: 5089.2196 | H950: 0 | I950: 584.03414 | J950: 4044.8954 | K950: 8117.0924 | L950: 262.86767 | M950: 3653.2445 | N950: =SUM(B950:M950) -> 34039.48 | P950: 0 | Q950: 0 | R950: 3.3525874 | S950: 1.8459314 | T950: 1.1728517 | U950: 2.8181484 | V950: 1.9746115 | W950: 2.2603126 | X950: 0.41015734 | Y950: 14.058739 | Z950: 3.7040511 | AA950: =SUM(O950:Z950) -> 31.59739 | AB950: Pay-as-you-go | AD950: 110.1 | AE950: 51.42 | AF950: 65 | AG950: 19.8 | AH950: 101.98 | AI950: 0.27 | AJ950: 11.88 | AK950: 81.17 | AL950: 162.45 | AM950: 6.61 | AN950: 73.44 | AO950: =SUM(AC950:AN950) -> 684.12
A951: SUB-460053662 | C951: 5208.7135 | D951: 1337.139 | E951: 2371.1417 | F951: 2223.905 | G951: 2951.7348 | H951: 401.81233 | I951: 785.06156 | J951: 3534.9556 | K951: 2500.7237 | L951: 3291.6458 | M951: 3384.3168 | N951: =SUM(B951:M951) -> 27991.15 | P951: 0.41467863 | Q951: 3.4933205 | R951: 0.31359203 | S951: 3.2341818 | T951: 6.6733167 | U951: 0.84185885 | V951: 4.1716722 | W951: 5.4395061 | X951: 0 | Y951: 5.5492368 | Z951: 4.156887 | AA951: =SUM(O951:Z951) -> 34.288251 | AB951: Pay-as-you-go | AD951: 104.27 | AE951: 27.12 | AF951: 47.53 | AG951: 44.84 | AH951: 59.67 | AI951: 8.13 | AJ951: 16.17 | AK951: 71.24 | AL951: 50.02 | AM951: 66.38 | AN951: 68.15 | AO951: =SUM(AC951:AN951) -> 563.52
A952: SUB-719844185 | C952: 5014.0863 | D952: 3215.6057 | E952: 159.10658 | F952: 1128.1899 | G952: 4426.5064 | H952: 595.37432 | I952: 548.63894 | J952: 2367.3918 | K952: 6626.3281 | L952: 1109.3063 | M952: 724.74798 | N952: =SUM(B952:M952) -> 25915.282 | P952: 1.0889759 | Q952: 1.4563872 | R952: 0 | S952: 2.4493563 | T952: 6.1765685 | U952: 11.821107 | V952: 2.3293418 | W952: 3.0301253 | X952: 0.69447143 | Y952: 3.5459295 | Z952: 1.5392782 | AA952: =SUM(O952:Z952) -> 34.131541 | AB952: Pay-as-you-go | AD952: 100.48 | AE952: 64.5 | AF952: 3.2 | AG952: 22.85 | AH952: 89.17 | AI952: 13 | AJ952: 11.25 | AK952: 47.72 | AL952: 132.63 | AM952: 22.56 | AN952: 14.68 | AO952: =SUM(AC952:AN952) -> 522.04
A953: SUB-571036263 | C953: 4180.8799 | D953: 2279.2318 | E953: 1075.7987 | F953: 1523.3522 | G953: 1439.1578 | H953: 661.56518 | I953: 5161.8154 | J953: 4260.4521 | K953: 1780.7454 | L953: 2335.6094 | M953: 1876.9912 | N953: =SUM(B953:M953) -> 26575.599 | P953: 0.046755479 | Q953: 17.231388 | R953: 0.3129928 | S953: 6.6335265 | T953: 3.1937214 | U953: 4.6393141 | V953: 2.4992258 | W953: 1.2565445 | X953: 9.5745005 | Y953: 11.077008 | Z953: 8.0202037 | AA953: =SUM(O953:Z953) -> 64.485181 | AB953: Pay-as-you-go | AD953: 83.71 | AE953: 47.22 | AF953: 21.61 | AG953: 31.11 | AH953: 29.16 | AI953: 13.69 | AJ953: 103.51 | AK953: 85.4 | AL953: 36.52 | AM953: 47.8 | AN953: 38.35 | AO953: =SUM(AC953:AN953) -> 538.08
A954: SUB-720331552 | C954: 3986.9135 | D954: 6238.2232 | E954: 2244.9442 | F954: 1717.2879 | G954: 339.7041 | H954: 5451.0595 | I954: 596.1593 | J954: 2185.4463 | K954: 1056.8739 | L954: 3156.7187 | M954: 4557.2186 | N954: =SUM(B954:M954) -> 31530.549 | P954: 8.0788459 | Q954: 4.1142585 | R954: 8.0662554 | S954: 0 | T954: 14.411465 | U954: 4.8176333 | V954: 0.18427497 | W954: 5.6750868 | X954: 0.17750264 | Y954: 7.4128378 | Z954: 0.43947722 | AA954: =SUM(O954:Z954) -> 53.377637 | AB954: Pay-as-you-go | AD954: 80.55 | AE954: 125.23 | AF954: 45.71 | AG954: 34.36 | AH954: 8.15 | AI954: 109.49 | AJ954: 12.03 | AK954: 44.26 | AL954: 21.23 | AM954: 63.86 | AN954: 91.25 | AO954: =SUM(AC954:AN954) -> 636.12
A955: SUB-653039003 | C955: 3189.7245 | D955: 0 | E955: 112.8603 | F955: 2318.5949 | G955: 982.75861 | H955: 6309.3869 | I955: 1647.3242 | J955: 14310.024 | K955: 4528.1777 | L955: 0 | M955: 1466.6296 | N955: =SUM(B955:M955) -> 34865.48 | P955: 1.1055033 | Q955: 1.0292283 | R955: 0.93950206 | S955: 4.580459 | T955: 2.0656366 | U955: 10.435644 | V955: 3.3742802 | W955: 19.297175 | X955: 8.8811675 | Y955: 0.74800421 | Z955: 9.9542266 | AA955: =SUM(O955:Z955) -> 62.410827 | AB955: Pay-as-you-go | AD955: 63.98 | AE955: 0.18 | AF955: 2.35 | AG955: 46.83 | AH955: 19.93 | AI955: 127.19 | AJ955: 33.32 | AK955: 288.02 | AL955: 91.39 | AM955: 0.09 | AN955: 30.24 | AO955: =SUM(AC955:AN955) -> 703.52
A956: SUB-975460557 | C956: 3175.6351 | D956: 3969.0512 | E956: 3242.8825 | F956: 1650.7161 | G956: 882.34254 | H956: 1825.312 | I956: 1533.6087 | J956: 0 | K956: 6793.5769 | L956: 1678.0995 | M956: 9342.7452 | N956: =SUM(B956:M956) -> 34093.97 | P956: 0 | Q956: 9.6370732 | R956: 10.64425 | S956: 0 | T956: 0.081302693 | U956: 5.4159945 | V956: 5.9521681 | W956: 1.6006319 | X956: 2.1384092 | Y956: 3.3199289 | Z956: 1.6563321 | AA956: =SUM(O956:Z956) -> 40.446091 | AB956: Pay-as-you-go | AD956: 63.52 | AE956: 80.3 | AF956: 65.85 | AG956: 33.02 | AH956: 17.75 | AI956: 37.06 | AJ956: 31.22 | AK956: 0.18 | AL956: 136.15 | AM956: 33.94 | AN956: 187.04 | AO956: =SUM(AC956:AN956) -> 686.03
A957: SUB-212766319 | C957: 2664.0766 | D957: 3063.4038 | E957: 1876.2939 | F957: 3048.4531 | G957: 704.35463 | H957: 1069.3947 | I957: 2704.1742 | J957: 7947.6785 | K957: 718.9787 | L957: 2939.4832 | M957: 329.93919 | N957: =SUM(B957:M957) -> 27066.231 | P957: 0 | Q957: 0.1572559 | R957: 0 | S957: 0.86068745 | T957: 7.3222978 | U957: 0 | V957: 5.7821693 | W957: 0.74302977 | X957: 8.9192903 | Y957: 2.734986 | Z957: 0.53455324 | AA957: =SUM(O957:Z957) -> 27.05427 | AB957: Pay-as-you-go | AD957: 53.3 | AE957: 61.37 | AF957: 37.54 | AG957: 61.07 | AH957: 14.82 | AI957: 21.4 | AJ957: 54.64 | AK957: 159.05 | AL957: 15.19 | AM957: 59.07 | AN957: 6.69 | AO957: =SUM(AC957:AN957) -> 544.14
...

Sheet S Size Pack
A1: S sized pack
A2: Tariff: 4.99 Euros
A3: Plan: 1GB of data, No free calls
A4: Assuming call rate to be 10 cents/min
A6: Customer_ID | B6: Excess_Data_Jan | C6: Excess_Data_Feb | D6: Excess_Data_Mar | E6: Excess_Data_Apr | F6: Excess_Data_May | G6: Excess_Data_Jun | H6: Excess_Data_Jul | I6: Excess_Data_Aug | J6: Excess_Data_Sep | K6: Excess_Data_Oct | L6: Excess_Data_Nov | M6: Excess_Data_Dec | N6: Total_Excess_data_S
A7: SUB-729143503 | B7: =IF(Combined_Data!B3> 1000, Combined_Data!B3 - 1000, 0) -> 27053.56 | C7: =IF(Combined_Data!C3> 1000, Combined_Data!C3 - 1000, 0) -> 1895.5485 | D7: =IF(Combined_Data!D3> 1000, Combined_Data!D3 - 1000, 0) -> 351.69367 | E7: =IF(Combined_Data!E3> 1000, Combined_Data!E3 - 1000, 0) -> 2756.5219 | F7: =IF(Combined_Data!F3> 1000, Combined_Data!F3 - 1000, 0) -> 0 | G7: =IF(Combined_Data!G3> 1000, Combined_Data!G3 - 1000, 0) -> 3012.203 | H7: =IF(Combined_Data!H3> 1000, Combined_Data!H3 - 1000, 0) -> 8166.6329 | I7: =IF(Combined_Data!I3> 1000, Combined_Data!I3 - 1000, 0) -> 4241.1959 | ... M7: =IF(Combined_Data!M3> 1000, Combined_Data!M3 - 1000, 0) -> 0 | N7: =SUM(B7:M7) -> 48073.827
A8: SUB-327259441 | B8: =IF(Combined_Data!B4> 1000, Combined_Data!B4 - 1000, 0) -> 26981.652 | C8: =IF(Combined_Data!C4> 1000, Combined_Data!C4 - 1000, 0) -> 0 | D8: =IF(Combined_Data!D4> 1000, Combined_Data!D4 - 1000, 0) -> 0 | E8: =IF(Combined_Data!E4> 1000, Combined_Data!E4 - 1000, 0) -> 0 | F8: =IF(Combined_Data!F4> 1000, Combined_Data!F4 - 1000, 0) -> 0 | G8: =IF(Combined_Data!G4> 1000, Combined_Data!G4 - 1000, 0) -> 3986.3074 | H8: =IF(Combined_Data!H4> 1000, Combined_Data!H4 - 1000, 0) -> 854.48703 | I8: =IF(Combined_Data!I4> 1000, Combined_Data!I4 - 1000, 0) -> 5695.5891 | ... M8: =IF(Combined_Data!M4> 1000, Combined_Data!M4 - 1000, 0) -> 1697.434 | N8: =SUM(B8:M8) -> 40107.469
A9: SUB-720199369 | B9: =IF(Combined_Data!B5> 1000, Combined_Data!B5 - 1000, 0) -> 23077.595 | C9: =IF(Combined_Data!C5> 1000, Combined_Data!C5 - 1000, 0) -> 1040.3707 | D9: =IF(Combined_Data!D5> 1000, Combined_Data!D5 - 1000, 0) -> 0 | E9: =IF(Combined_Data!E5> 1000, Combined_Data!E5 - 1000, 0) -> 1976.9148 | F9: =IF(Combined_Data!F5> 1000, Combined_Data!F5 - 1000, 0) -> 2284.5485 | G9: =IF(Combined_Data!G5> 1000, Combined_Data!G5 - 1000, 0) -> 0 | H9: =IF(Combined_Data!H5> 1000, Combined_Data!H5 - 1000, 0) -> 0 | I9: =IF(Combined_Data!I5> 1000, Combined_Data!I5 - 1000, 0) -> 4062.1182 | ... M9: =IF(Combined_Data!M5> 1000, Combined_Data!M5 - 1000, 0) -> 0 | N9: =SUM(B9:M9) -> 34420.384
A10: SUB-115774364 | B10: =IF(Combined_Data!B6> 1000, Combined_Data!B6 - 1000, 0) -> 22074.756 | C10: =IF(Combined_Data!C6> 1000, Combined_Data!C6 - 1000, 0) -> 1785.5024 | D10: =IF(Combined_Data!D6> 1000, Combined_Data!D6 - 1000, 0) -> 0 | E10: =IF(Combined_Data!E6> 1000, Combined_Data!E6 - 1000, 0) -> 2283.7711 | F10: =IF(Combined_Data!F6> 1000, Combined_Data!F6 - 1000, 0) -> 6459.8083 | G10: =IF(Combined_Data!G6> 1000, Combined_Data!G6 - 1000, 0) -> 2168.5675 | H10: =IF(Combined_Data!H6> 1000, Combined_Data!H6 - 1000, 0) -> 907.47372 | I10: =IF(Combined_Data!I6> 1000, Combined_Data!I6 - 1000, 0) -> 0 | ... M10: =IF(Combined_Data!M6> 1000, Combined_Data!M6 - 1000, 0) -> 6622.4986 | N10: =SUM(B10:M10) -> 45387.462
A11: SUB-687511952 | B11: =IF(Combined_Data!B7> 1000, Combined_Data!B7 - 1000, 0) -> 21979.493 | C11: =IF(Combined_Data!C7> 1000, Combined_Data!C7 - 1000, 0) -> 1122.315 | D11: =IF(Combined_Data!D7> 1000, Combined_Data!D7 - 1000, 0) -> 0 | E11: =IF(Combined_Data!E7> 1000, Combined_Data!E7 - 1000, 0) -> 4628.9233 | F11: =IF(Combined_Data!F7> 1000, Combined_Data!F7 - 1000, 0) -> 0 | G11: =IF(Combined_Data!G7> 1000, Combined_Data!G7 - 1000, 0) -> 865.49224 | H11: =IF(Combined_Data!H7> 1000, Combined_Data!H7 - 1000, 0) -> 0 | I11: =IF(Combined_Data!I7> 1000, Combined_Data!I7 - 1000, 0) -> 8671.7792 | ... M11: =IF(Combined_Data!M7> 1000, Combined_Data!M7 - 1000, 0) -> 642.51217 | N11: =SUM(B11:M11) -> 47666.923
A12: SUB-884111294 | B12: =IF(Combined_Data!B8> 1000, Combined_Data!B8 - 1000, 0) -> 20172.886 | C12: =IF(Combined_Data!C8> 1000, Combined_Data!C8 - 1000, 0) -> 523.68765 | D12: =IF(Combined_Data!D8> 1000, Combined_Data!D8 - 1000, 0) -> 485.30579 | E12: =IF(Combined_Data!E8> 1000, Combined_Data!E8 - 1000, 0) -> 3193.1236 | F12: =IF(Combined_Data!F8> 1000, Combined_Data!F8 - 1000, 0) -> 956.61231 | G12: =IF(Combined_Data!G8> 1000, Combined_Data!G8 - 1000, 0) -> 901.25347 | H12: =IF(Combined_Data!H8> 1000, Combined_Data!H8 - 1000, 0) -> 2119.8269 | I12: =IF(Combined_Data!I8> 1000, Combined_Data!I8 - 1000, 0) -> 1239.8238 | ... M12: =IF(Combined_Data!M8> 1000, Combined_Data!M8 - 1000, 0) -> 5059.3035 | N12: =SUM(B12:M12) -> 48452.956
A13: SUB-754009185 | B13: =IF(Combined_Data!B9> 1000, Combined_Data!B9 - 1000, 0) -> 16677.832 | C13: =IF(Combined_Data!C9> 1000, Combined_Data!C9 - 1000, 0) -> 3761.3302 | D13: =IF(Combined_Data!D9> 1000, Combined_Data!D9 - 1000, 0) -> 2058.4981 | E13: =IF(Combined_Data!E9> 1000, Combined_Data!E9 - 1000, 0) -> 8399.811 | F13: =IF(Combined_Data!F9> 1000, Combined_Data!F9 - 1000, 0) -> 7675.879 | G13: =IF(Combined_Data!G9> 1000, Combined_Data!G9 - 1000, 0) -> 4734.8376 | H13: =IF(Combined_Data!H9> 1000, Combined_Data!H9 - 1000, 0) -> 2587.2216 | I13: =IF(Combined_Data!I9> 1000, Combined_Data!I9 - 1000, 0) -> 2564.4166 | ... M13: =IF(Combined_Data!M9> 1000, Combined_Data!M9 - 1000, 0) -> 1312.6221 | N13: =SUM(B13:M13) -> 51078.505
A14: SUB-907933772 | B14: =IF(Combined_Data!B10> 1000, Combined_Data!B10 - 1000, 0) -> 16562.336 | C14: =IF(Combined_Data!C10> 1000, Combined_Data!C10 - 1000, 0) -> 588.66946 | D14: =IF(Combined_Data!D10> 1000, Combined_Data!D10 - 1000, 0) -> 873.92561 | E14: =IF(Combined_Data!E10> 1000, Combined_Data!E10 - 1000, 0) -> 11191.94 | F14: =IF(Combined_Data!F10> 1000, Combined_Data!F10 - 1000, 0) -> 2104.8013 | G14: =IF(Combined_Data!G10> 1000, Combined_Data!G10 - 1000, 0) -> 559.31436 | H14: =IF(Combined_Data!H10> 1000, Combined_Data!H10 - 1000, 0) -> 3198.5673 | I14: =IF(Combined_Data!I10> 1000, Combined_Data!I10 - 1000, 0) -> 0 | ... M14: =IF(Combined_Data!M10> 1000, Combined_Data!M10 - 1000, 0) -> 0 | N14: =SUM(B14:M14) -> 35785.623
A15: SUB-219686190 | B15: =IF(Combined_Data!B11> 1000, Combined_Data!B11 - 1000, 0) -> 16310.819 | C15: =IF(Combined_Data!C11> 1000, Combined_Data!C11 - 1000, 0) -> 600.9242 | D15: =IF(Combined_Data!D11> 1000, Combined_Data!D11 - 1000, 0) -> 3071.8053 | E15: =IF(Combined_Data!E11> 1000, Combined_Data!E11 - 1000, 0) -> 0 | F15: =IF(Combined_Data!F11> 1000, Combined_Data!F11 - 1000, 0) -> 0 | G15: =IF(Combined_Data!G11> 1000, Combined_Data!G11 - 1000, 0) -> 5817.1882 | H15: =IF(Combined_Data!H11> 1000, Combined_Data!H11 - 1000, 0) -> 511.49085 | I15: =IF(Combined_Data!I11> 1000, Combined_Data!I11 - 1000, 0) -> 614.10888 | ... M15: =IF(Combined_Data!M11> 1000, Combined_Data!M11 - 1000, 0) -> 4663.6196 | N15: =SUM(B15:M15) -> 42921.91
A16: SUB-275406642 | B16: =IF(Combined_Data!B12> 1000, Combined_Data!B12 - 1000, 0) -> 15752.503 | C16: =IF(Combined_Data!C12> 1000, Combined_Data!C12 - 1000, 0) -> 5126.3628 | D16: =IF(Combined_Data!D12> 1000, Combined_Data!D12 - 1000, 0) -> 1972.6152 | E16: =IF(Combined_Data!E12> 1000, Combined_Data!E12 - 1000, 0) -> 3473.5263 | F16: =IF(Combined_Data!F12> 1000, Combined_Data!F12 - 1000, 0) -> 4774.8251 | G16: =IF(Combined_Data!G12> 1000, Combined_Data!G12 - 1000, 0) -> 1388.7042 | H16: =IF(Combined_Data!H12> 1000, Combined_Data!H12 - 1000, 0) -> 5406.1825 | I16: =IF(Combined_Data!I12> 1000, Combined_Data!I12 - 1000, 0) -> 414.01455 | ... M16: =IF(Combined_Data!M12> 1000, Combined_Data!M12 - 1000, 0) -> 3306.3377 | N16: =SUM(B16:M16) -> 46732.684
A17: SUB-475178203 | B17: =IF(Combined_Data!B13> 1000, Combined_Data!B13 - 1000, 0) -> 15234.974 | C17: =IF(Combined_Data!C13> 1000, Combined_Data!C13 - 1000, 0) -> 2934.7617 | D17: =IF(Combined_Data!D13> 1000, Combined_Data!D13 - 1000, 0) -> 4727.4151 | E17: =IF(Combined_Data!E13> 1000, Combined_Data!E13 - 1000, 0) -> 0 | F17: =IF(Combined_Data!F13> 1000, Combined_Data!F13 - 1000, 0) -> 6942.5962 | G17: =IF(Combined_Data!G13> 1000, Combined_Data!G13 - 1000, 0) -> 10273.978 | H17: =IF(Combined_Data!H13> 1000, Combined_Data!H13 - 1000, 0) -> 1245.1036 | I17: =IF(Combined_Data!I13> 1000, Combined_Data!I13 - 1000, 0) -> 4506.8814 | ... M17: =IF(Combined_Data!M13> 1000, Combined_Data!M13 - 1000, 0) -> 2442.1968 | N17: =SUM(B17:M17) -> 55897.179
A18: SUB-384428935 | B18: =IF(Combined_Data!B14> 1000, Combined_Data!B14 - 1000, 0) -> 15201.279 | C18: =IF(Combined_Data!C14> 1000, Combined_Data!C14 - 1000, 0) -> 976.36773 | D18: =IF(Combined_Data!D14> 1000, Combined_Data!D14 - 1000, 0) -> 334.06983 | E18: =IF(Combined_Data!E14> 1000, Combined_Data!E14 - 1000, 0) -> 5880.8346 | F18: =IF(Combined_Data!F14> 1000, Combined_Data!F14 - 1000, 0) -> 1098.5512 | G18: =IF(Combined_Data!G14> 1000, Combined_Data!G14 - 1000, 0) -> 613.6047 | H18: =IF(Combined_Data!H14> 1000, Combined_Data!H14 - 1000, 0) -> 941.86939 | I18: =IF(Combined_Data!I14> 1000, Combined_Data!I14 - 1000, 0) -> 2510.1076 | ... M18: =IF(Combined_Data!M14> 1000, Combined_Data!M14 - 1000, 0) -> 134.30073 | N18: =SUM(B18:M18) -> 29643.934
... A1006: SUB-961271099 | B1006: =IF(Combined_Data!B1002> 1000, Combined_Data!B1002 - 1000, 0) -> 0 | C1006: =IF(Combined_Data!C1002> 1000, Combined_Data!C1002 - 1000, 0) -> 0 | D1006: =IF(Combined_Data!D1002> 1000, Combined_Data!D1002 - 1000, 0) -> 0 | E1006: =IF(Combined_Data!E1002> 1000, Combined_Data!E1002 - 1000, 0) -> 16077.526 | F1006: =IF(Combined_Data!F1002> 1000, Combined_Data!F1002 - 1000, 0) -> 3294.2083 | G1006: =IF(Combined_Data!G1002> 1000, Combined_Data!G1002 - 1000, 0) -> 360.20841 | H1006: =IF(Combined_Data!H1002> 1000, Combined_Data!H1002 - 1000, 0) -> 0 | I1006: =IF(Combined_Data!I1002> 1000, Combined_Data!I1002 - 1000, 0) -> 0 | ... M1006: =IF(Combined_Data!M1002> 1000, Combined_Data!M1002 - 1000, 0) -> 781.48964 | N1006: =SUM(B1006:M1006) -> 23702.129

Sheet Excess data S Pack
A1: Excess pack details: 1GB for 5 Euros
A2: No. of customers Change | B2: =COUNTIFS(T8:T1007,">0") -> 1000
A3: No. of customer do not change | B3: =COUNTIFS(T8:T1008,"<0") -> 0
A5: Total revenue | B5: =SUM(R8:R1007) -> 247407.15 | C5: Assuming that all customers would choose this package
A7: Customer_ID | B7: Plan | C7: Excess_Data_jan | D7: Excess_Data_Feb | E7: Excess_Data_Mar | F7: Excess_Data_Apr | G7: Excess_Data_May | H7: Excess_Data_Jun | I7: Excess_Data_Jul | J7: Excess_Data_Aug | K7: Excess_Data_Sep | L7: Excess_Data_Oct | M7: Excess_Data_Nov | N7: Excess_Data_Dec | O7: Total Excess Data Purchased | P7: Cost of excess data purchased | Q7: Cost_Total_Talktime_S | R7: Total Billing S package | S7: Total billing current tariff | T7: Difference between Current and S pack
A8: SUB-729143503 | B8: Reduced rate | C8: =CEILING('S Size Pack'!B7/1000,1) -> 28 | D8: =CEILING('S Size Pack'!C7/1000,1) -> 2 | E8: =CEILING('S Size Pack'!D7/1000,1) -> 1 | F8: =CEILING('S Size Pack'!E7/1000,1) -> 3 | G8: =CEILING('S Size Pack'!F7/1000,1) -> 0 | H8: =CEILING('S Size Pack'!G7/1000,1) -> 4 | I8: =CEILING('S Size Pack'!H7/1000,1) -> 9 | J8: =CEILING('S Size Pack'!I7/1000,1) -> 5 | ... N8: =CEILING('S Size Pack'!M7/1000,1) -> 0 | O8: =SUM(C8:N8) -> 53 | P8: =O8*5 -> 265 | Q8: 6.0885491 | R8: =P8+Q8+4.99*12 -> 330.96855 | S8: 700.39 | T8: =S8-R8 -> 369.42145
A9: SUB-327259441 | B9: Reduced rate | C9: =CEILING('S Size Pack'!B8/1000,1) -> 27 | D9: =CEILING('S Size Pack'!C8/1000,1) -> 0 | E9: =CEILING('S Size Pack'!D8/1000,1) -> 0 | F9: =CEILING('S Size Pack'!E8/1000,1) -> 0 | G9: =CEILING('S Size Pack'!F8/1000,1) -> 0 | H9: =CEILING('S Size Pack'!G8/1000,1) -> 4 | I9: =CEILING('S Size Pack'!H8/1000,1) -> 1 | J9: =CEILING('S Size Pack'!I8/1000,1) -> 6 | ... N9: =CEILING('S Size Pack'!M8/1000,1) -> 2 | O9: =SUM(C9:N9) -> 41 | P9: =O9*5 -> 205 | Q9: 3.563493 | R9: =P9+Q9+4.99*12 -> 268.44349 | S9: 625.11 | T9: =S9-R9 -> 356.66651
A10: SUB-720199369 | B10: Reduced rate | C10: =CEILING('S Size Pack'!B9/1000,1) -> 24 | D10: =CEILING('S Size Pack'!C9/1000,1) -> 2 | E10: =CEILING('S Size Pack'!D9/1000,1) -> 0 | F10: =CEILING('S Size Pack'!E9/1000,1) -> 2 | G10: =CEILING('S Size Pack'!F9/1000,1) -> 3 | H10: =CEILING('S Size Pack'!G9/1000,1) -> 0 | I10: =CEILING('S Size Pack'!H9/1000,1) -> 0 | J10: =CEILING('S Size Pack'!I9/1000,1) -> 5 | ... N10: =CEILING('S Size Pack'!M9/1000,1) -> 0 | O10: =SUM(C10:N10) -> 39 | P10: =O10*5 -> 195 | Q10: 4.4183788 | R10: =P10+Q10+4.99*12 -> 259.29838 | S10: 560.48 | T10: =S10-R10 -> 301.18162
A11: SUB-115774364 | B11: Reduced rate | C11: =CEILING('S Size Pack'!B10/1000,1) -> 23 | D11: =CEILING('S Size Pack'!C10/1000,1) -> 2 | E11: =CEILING('S Size Pack'!D10/1000,1) -> 0 | F11: =CEILING('S Size Pack'!E10/1000,1) -> 3 | G11: =CEILING('S Size Pack'!F10/1000,1) -> 7 | H11: =CEILING('S Size Pack'!G10/1000,1) -> 3 | I11: =CEILING('S Size Pack'!H10/1000,1) -> 1 | J11: =CEILING('S Size Pack'!I10/1000,1) -> 0 | ... N11: =CEILING('S Size Pack'!M10/1000,1) -> 7 | O11: =SUM(C11:N11) -> 51 | P11: =O11*5 -> 255 | Q11: 4.3565315 | R11: =P11+Q11+4.99*12 -> 319.23653 | S11: 682.55 | T11: =S11-R11 -> 363.31347
A12: SUB-687511952 | B12: Reduced rate | C12: =CEILING('S Size Pack'!B11/1000,1) -> 22 | D12: =CEILING('S Size Pack'!C11/1000,1) -> 2 | E12: =CEILING('S Size Pack'!D11/1000,1) -> 0 | F12: =CEILING('S Size Pack'!E11/1000,1) -> 5 | G12: =CEILING('S Size Pack'!F11/1000,1) -> 0 | H12: =CEILING('S Size Pack'!G11/1000,1) -> 1 | I12: =CEILING('S Size Pack'!H11/1000,1) -> 0 | J12: =CEILING('S Size Pack'!I11/1000,1) -> 9 | ... N12: =CEILING('S Size Pack'!M11/1000,1) -> 1 | O12: =SUM(C12:N12) -> 50 | P12: =O12*5 -> 250 | Q12: 3.6037017 | R12: =P12+Q12+4.99*12 -> 313.4837 | S12: 705.08 | T12: =S12-R12 -> 391.5963
A13: SUB-884111294 | B13: Reduced rate | C13: =CEILING('S Size Pack'!B12/1000,1) -> 21 | D13: =CEILING('S Size Pack'!C12/1000,1) -> 1 | E13: =CEILING('S Size Pack'!D12/1000,1) -> 1 | F13: =CEILING('S Size Pack'!E12/1000,1) -> 4 | G13: =CEILING('S Size Pack'!F12/1000,1) -> 1 | H13: =CEILING('S Size Pack'!G12/1000,1) -> 1 | I13: =CEILING('S Size Pack'!H12/1000,1) -> 3 | J13: =CEILING('S Size Pack'!I12/1000,1) -> 2 | ... N13: =CEILING('S Size Pack'!M12/1000,1) -> 6 | O13: =SUM(C13:N13) -> 55 | P13: =O13*5 -> 275 | Q13: 7.6831726 | R13: =P13+Q13+4.99*12 -> 342.56317 | S13: 728.61 | T13: =S13-R13 -> 386.04683
A14: SUB-754009185 | B14: Reduced rate | C14: =CEILING('S Size Pack'!B13/1000,1) -> 17 | D14: =CEILING('S Size Pack'!C13/1000,1) -> 4 | E14: =CEILING('S Size Pack'!D13/1000,1) -> 3 | F14: =CEILING('S Size Pack'!E13/1000,1) -> 9 | G14: =CEILING('S Size Pack'!F13/1000,1) -> 8 | H14: =CEILING('S Size Pack'!G13/1000,1) -> 5 | I14: =CEILING('S Size Pack'!H13/1000,1) -> 3 | J14: =CEILING('S Size Pack'!I13/1000,1) -> 3 | ... N14: =CEILING('S Size Pack'!M13/1000,1) -> 2 | O14: =SUM(C14:N14) -> 57 | P14: =O14*5 -> 285 | Q14: 3.4988229 | R14: =P14+Q14+4.99*12 -> 348.37882 | S14: 744.32 | T14: =S14-R14 -> 395.94118
A15: SUB-907933772 | B15: Reduced rate | C15: =CEILING('S Size Pack'!B14/1000,1) -> 17 | D15: =CEILING('S Size Pack'!C14/1000,1) -> 1 | E15: =CEILING('S Size Pack'!D14/1000,1) -> 1 | F15: =CEILING('S Size Pack'!E14/1000,1) -> 12 | G15: =CEILING('S Size Pack'!F14/1000,1) -> 3 | H15: =CEILING('S Size Pack'!G14/1000,1) -> 1 | I15: =CEILING('S Size Pack'!H14/1000,1) -> 4 | J15: =CEILING('S Size Pack'!I14/1000,1) -> 0 | ... N15: =CEILING('S Size Pack'!M14/1000,1) -> 0 | O15: =SUM(C15:N15) -> 40 | P15: =O15*5 -> 200 | Q15: 3.4044027 | R15: =P15+Q15+4.99*12 -> 263.2844 | S15: 570.48 | T15: =S15-R15 -> 307.1956
A16: SUB-219686190 | B16: Reduced rate | C16: =CEILING('S Size Pack'!B15/1000,1) -> 17 | D16: =CEILING('S Size Pack'!C15/1000,1) -> 1 | E16: =CEILING('S Size Pack'!D15/1000,1) -> 4 | F16: =CEILING('S Size Pack'!E15/1000,1) -> 0 | G16: =CEILING('S Size Pack'!F15/1000,1) -> 0 | H16: =CEILING('S Size Pack'!G15/1000,1) -> 6 | I16: =CEILING('S Size Pack'!H15/1000,1) -> 1 | J16: =CEILING('S Size Pack'!I15/1000,1) -> 1 | ... N16: =CEILING('S Size Pack'!M15/1000,1) -> 5 | O16: =SUM(C16:N16) -> 47 | P16: =O16*5 -> 235 | Q16: 3.9516809 | R16: =P16+Q16+4.99*12 -> 298.83168 | S16: 651.52 | T16: =S16-R16 -> 352.68832
A17: SUB-275406642 | B17: Reduced rate | C17: =CEILING('S Size Pack'!B16/1000,1) -> 16 | D17: =CEILING('S Size Pack'!C16/1000,1) -> 6 | E17: =CEILING('S Size Pack'!D16/1000,1) -> 2 | F17: =CEILING('S Size Pack'!E16/1000,1) -> 4 | G17: =CEILING('S Size Pack'!F16/1000,1) -> 5 | H17: =CEILING('S Size Pack'!G16/1000,1) -> 2 | I17: =CEILING('S Size Pack'!H16/1000,1) -> 6 | J17: =CEILING('S Size Pack'!I16/1000,1) -> 1 | ... N17: =CEILING('S Size Pack'!M16/1000,1) -> 4 | O17: =SUM(C17:N17) -> 53 | P17: =O17*5 -> 265 | Q17: 5.7768352 | R17: =P17+Q17+4.99*12 -> 330.65684 | S17: 710.47 | T17: =S17-R17 -> 379.81316
A18: SUB-475178203 | B18: Reduced rate | C18: =CEILING('S Size Pack'!B17/1000,1) -> 16 | D18: =CEILING('S Size Pack'!C17/1000,1) -> 3 | E18: =CEILING('S Size Pack'!D17/1000,1) -> 5 | F18: =CEILING('S Size Pack'!E17/1000,1) -> 0 | G18: =CEILING('S Size Pack'!F17/1000,1) -> 7 | H18: =CEILING('S Size Pack'!G17/1000,1) -> 11 | I18: =CEILING('S Size Pack'!H17/1000,1) -> 2 | J18: =CEILING('S Size Pack'!I17/1000,1) -> 5 | ... N18: =CEILING('S Size Pack'!M17/1000,1) -> 3 | O18: =SUM(C18:N18) -> 60 | P18: =O18*5 -> 300 | Q18: 5.3524702 | R18: =P18+Q18+4.99*12 -> 365.23247 | S18: 788.21 | T18: =S18-R18 -> 422.97753
A19: SUB-384428935 | B19: Reduced rate | C19: =CEILING('S Size Pack'!B18/1000,1) -> 16 | D19: =CEILING('S Size Pack'!C18/1000,1) -> 1 | E19: =CEILING('S Size Pack'!D18/1000,1) -> 1 | F19: =CEILING('S Size Pack'!E18/1000,1) -> 6 | G19: =CEILING('S Size Pack'!F18/1000,1) -> 2 | H19: =CEILING('S Size Pack'!G18/1000,1) -> 1 | I19: =CEILING('S Size Pack'!H18/1000,1) -> 1 | J19: =CEILING('S Size Pack'!I18/1000,1) -> 3 | ... N19: =CEILING('S Size Pack'!M18/1000,1) -> 1 | O19: =SUM(C19:N19) -> 35 | P19: =O19*5 -> 175 | Q19: 8.6843491 | R19: =P19+Q19+4.99*12 -> 243.56435 | S19: 530.98 | T19: =S19-R19 -> 287.41565
... A1007: SUB-961271099 | B1007: Pay-as-you-go | C1007: =CEILING('S Size Pack'!B1006/1000,1) -> 0 | D1007: =CEILING('S Size Pack'!C1006/1000,1) -> 0 | E1007: =CEILING('S Size Pack'!D1006/1000,1) -> 0 | F1007: =CEILING('S Size Pack'!E1006/1000,1) -> 17 | G1007: =CEILING('S Size Pack'!F1006/1000,1) -> 4 | H1007: =CEILING('S Size Pack'!G1006/1000,1) -> 1 | I1007: =CEILING('S Size Pack'!H1006/1000,1) -> 0 | J1007: =CEILING('S Size Pack'!I1006/1000,1) -> 0 | ... N1007: =CEILING('S Size Pack'!M1006/1000,1) -> 1 | O1007: =SUM(C1007:N1007) -> 28 | P1007: =O1007*5 -> 140 | Q1007: 2.3575096 | R1007: =P1007+Q1007+4.99*12 -> 202.23751 | S1007: 623.28 | T1007: =S1007-R1007 -> 421.04249

Sheet M Size Pack
A1: M sized pack
A2: Tariff: 9.99 Euros
A3: Plan: 5GB of data, 60 Mins free calls
A4: Assuming call rate to be 10 cents/min
A7: Customer_ID | B7: Excess_Data_jan | C7: Excess_Data_Feb | D7: Excess_Data_Mar | E7: Excess_Data_Apr | F7: Excess_Data_May | G7: Excess_Data_Jun | H7: Excess_Data_Jul | I7: Excess_Data_Aug | J7: Excess_Data_Sep | K7: Excess_Data_Oct | L7: Excess_Data_Nov | M7: Excess_Data_Dec | N7: Total_Excess_data_S
A8: SUB-729143503 | B8: =IF(Combined_Data!B3 > 5000, Combined_Data!B3 - 5000, 0) -> 23053.56 | C8: =IF(Combined_Data!C3 > 5000, Combined_Data!C3 - 5000, 0) -> 0 | D8: =IF(Combined_Data!D3 > 5000, Combined_Data!D3 - 5000, 0) -> 0 | E8: =IF(Combined_Data!E3 > 5000, Combined_Data!E3 - 5000, 0) -> 0 | F8: =IF(Combined_Data!F3 > 5000, Combined_Data!F3 - 5000, 0) -> 0 | G8: =IF(Combined_Data!G3 > 5000, Combined_Data!G3 - 5000, 0) -> 0 | H8: =IF(Combined_Data!H3 > 5000, Combined_Data!H3 - 5000, 0) -> 4166.6329 | I8: =IF(Combined_Data!I3 > 5000, Combined_Data!I3 - 5000, 0) -> 241.19595 | ... M8: =IF(Combined_Data!M3 > 5000, Combined_Data!M3 - 5000, 0) -> 0 | N8: =SUM(B8:M8) -> 27461.389
A9: SUB-327259441 | B9: =IF(Combined_Data!B4 > 5000, Combined_Data!B4 - 5000, 0) -> 22981.652 | C9: =IF(Combined_Data!C4 > 5000, Combined_Data!C4 - 5000, 0) -> 0 | D9: =IF(Combined_Data!D4 > 5000, Combined_Data!D4 - 5000, 0) -> 0 | E9: =IF(Combined_Data!E4 > 5000, Combined_Data!E4 - 5000, 0) -> 0 | F9: =IF(Combined_Data!F4 > 5000, Combined_Data!F4 - 5000, 0) -> 0 | G9: =IF(Combined_Data!G4 > 5000, Combined_Data!G4 - 5000, 0) -> 0 | H9: =IF(Combined_Data!H4 > 5000, Combined_Data!H4 - 5000, 0) -> 0 | I9: =IF(Combined_Data!I4 > 5000, Combined_Data!I4 - 5000, 0) -> 1695.5891 | ... M9: =IF(Combined_Data!M4 > 5000, Combined_Data!M4 - 5000, 0) -> 0 | N9: =SUM(B9:M9) -> 24677.241
A10: SUB-720199369 | B10: =IF(Combined_Data!B5 > 5000, Combined_Data!B5 - 5000, 0) -> 19077.595 | C10: =IF(Combined_Data!C5 > 5000, Combined_Data!C5 - 5000, 0) -> 0 | D10: =IF(Combined_Data!D5 > 5000, Combined_Data!D5 - 5000, 0) -> 0 | E10: =IF(Combined_Data!E5 > 5000, Combined_Data!E5 - 5000, 0) -> 0 | F10: =IF(Combined_Data!F5 > 5000, Combined_Data!F5 - 5000, 0) -> 0 | G10: =IF(Combined_Data!G5 > 5000, Combined_Data!G5 - 5000, 0) -> 0 | H10: =IF(Combined_Data!H5 > 5000, Combined_Data!H5 - 5000, 0) -> 0 | I10: =IF(Combined_Data!I5 > 5000, Combined_Data!I5 - 5000, 0) -> 62.11823 | ... M10: =IF(Combined_Data!M5 > 5000, Combined_Data!M5 - 5000, 0) -> 0 | N10: =SUM(B10:M10) -> 19139.713
A11: SUB-115774364 | B11: =IF(Combined_Data!B6 > 5000, Combined_Data!B6 - 5000, 0) -> 18074.756 | C11: =IF(Combined_Data!C6 > 5000, Combined_Data!C6 - 5000, 0) -> 0 | D11: =IF(Combined_Data!D6 > 5000, Combined_Data!D6 - 5000, 0) -> 0 | E11: =IF(Combined_Data!E6 > 5000, Combined_Data!E6 - 5000, 0) -> 0 | F11: =IF(Combined_Data!F6 > 5000, Combined_Data!F6 - 5000, 0) -> 2459.8083 | G11: =IF(Combined_Data!G6 > 5000, Combined_Data!G6 - 5000, 0) -> 0 | H11: =IF(Combined_Data!H6 > 5000, Combined_Data!H6 - 5000, 0) -> 0 | I11: =IF(Combined_Data!I6 > 5000, Combined_Data!I6 - 5000, 0) -> 0 | ... M11: =IF(Combined_Data!M6 > 5000, Combined_Data!M6 - 5000, 0) -> 2622.4986 | N11: =SUM(B11:M11) -> 23157.063
A12: SUB-687511952 | B12: =IF(Combined_Data!B7 > 5000, Combined_Data!B7 - 5000, 0) -> 17979.493 | C12: =IF(Combined_Data!C7 > 5000, Combined_Data!C7 - 5000, 0) -> 0 | D12: =IF(Combined_Data!D7 > 5000, Combined_Data!D7 - 5000, 0) -> 0 | E12: =IF(Combined_Data!E7 > 5000, Combined_Data!E7 - 5000, 0) -> 628.92328 | F12: =IF(Combined_Data!F7 > 5000, Combined_Data!F7 - 5000, 0) -> 0 | G12: =IF(Combined_Data!G7 > 5000, Combined_Data!G7 - 5000, 0) -> 0 | H12: =IF(Combined_Data!H7 > 5000, Combined_Data!H7 - 5000, 0) -> 0 | I12: =IF(Combined_Data!I7 > 5000, Combined_Data!I7 - 5000, 0) -> 4671.7792 | ... M12: =IF(Combined_Data!M7 > 5000, Combined_Data!M7 - 5000, 0) -> 0 | N12: =SUM(B12:M12) -> 26108.872
A13: SUB-884111294 | B13: =IF(Combined_Data!B8 > 5000, Combined_Data!B8 - 5000, 0) -> 16172.886 | C13: =IF(Combined_Data!C8 > 5000, Combined_Data!C8 - 5000, 0) -> 0 | D13: =IF(Combined_Data!D8 > 5000, Combined_Data!D8 - 5000, 0) -> 0 | E13: =IF(Combined_Data!E8 > 5000, Combined_Data!E8 - 5000, 0) -> 0 | F13: =IF(Combined_Data!F8 > 5000, Combined_Data!F8 - 5000, 0) -> 0 | G13: =IF(Combined_Data!G8 > 5000, Combined_Data!G8 - 5000, 0) -> 0 | H13: =IF(Combined_Data!H8 > 5000, Combined_Data!H8 - 5000, 0) -> 0 | I13: =IF(Combined_Data!I8 > 5000, Combined_Data!I8 - 5000, 0) -> 0 | ... M13: =IF(Combined_Data!M8 > 5000, Combined_Data!M8 - 5000, 0) -> 1059.3035 | N13: =SUM(B13:M13) -> 22384.356
A14: SUB-754009185 | B14: =IF(Combined_Data!B9 > 5000, Combined_Data!B9 - 5000, 0) -> 12677.832 | C14: =IF(Combined_Data!C9 > 5000, Combined_Data!C9 - 5000, 0) -> 0 | D14: =IF(Combined_Data!D9 > 5000, Combined_Data!D9 - 5000, 0) -> 0 | E14: =IF(Combined_Data!E9 > 5000, Combined_Data!E9 - 5000, 0) -> 4399.811 | F14: =IF(Combined_Data!F9 > 5000, Combined_Data!F9 - 5000, 0) -> 3675.879 | G14: =IF(Combined_Data!G9 > 5000, Combined_Data!G9 - 5000, 0) -> 734.83765 | H14: =IF(Combined_Data!H9 > 5000, Combined_Data!H9 - 5000, 0) -> 0 | I14: =IF(Combined_Data!I9 > 5000, Combined_Data!I9 - 5000, 0) -> 0 | ... M14: =IF(Combined_Data!M9 > 5000, Combined_Data!M9 - 5000, 0) -> 0 | N14: =SUM(B14:M14) -> 21488.36
A15: SUB-907933772 | B15: =IF(Combined_Data!B10 > 5000, Combined_Data!B10 - 5000, 0) -> 12562.336 | C15: =IF(Combined_Data!C10 > 5000, Combined_Data!C10 - 5000, 0) -> 0 | D15: =IF(Combined_Data!D10 > 5000, Combined_Data!D10 - 5000, 0) -> 0 | E15: =IF(Combined_Data!E10 > 5000, Combined_Data!E10 - 5000, 0) -> 7191.9403 | F15: =IF(Combined_Data!F10 > 5000, Combined_Data!F10 - 5000, 0) -> 0 | G15: =IF(Combined_Data!G10 > 5000, Combined_Data!G10 - 5000, 0) -> 0 | H15: =IF(Combined_Data!H10 > 5000, Combined_Data!H10 - 5000, 0) -> 0 | I15: =IF(Combined_Data!I10 > 5000, Combined_Data!I10 - 5000, 0) -> 0 | ... M15: =IF(Combined_Data!M10 > 5000, Combined_Data!M10 - 5000, 0) -> 0 | N15: =SUM(B15:M15) -> 19754.276
A16: SUB-219686190 | B16: =IF(Combined_Data!B11 > 5000, Combined_Data!B11 - 5000, 0) -> 12310.819 | C16: =IF(Combined_Data!C11 > 5000, Combined_Data!C11 - 5000, 0) -> 0 | D16: =IF(Combined_Data!D11 > 5000, Combined_Data!D11 - 5000, 0) -> 0 | E16: =IF(Combined_Data!E11 > 5000, Combined_Data!E11 - 5000, 0) -> 0 | F16: =IF(Combined_Data!F11 > 5000, Combined_Data!F11 - 5000, 0) -> 0 | G16: =IF(Combined_Data!G11 > 5000, Combined_Data!G11 - 5000, 0) -> 1817.1882 | H16: =IF(Combined_Data!H11 > 5000, Combined_Data!H11 - 5000, 0) -> 0 | I16: =IF(Combined_Data!I11 > 5000, Combined_Data!I11 - 5000, 0) -> 0 | ... M16: =IF(Combined_Data!M11 > 5000, Combined_Data!M11 - 5000, 0) -> 663.61962 | N16: =SUM(B16:M16) -> 21400.348
A17: SUB-275406642 | B17: =IF(Combined_Data!B12 > 5000, Combined_Data!B12 - 5000, 0) -> 11752.503 | C17: =IF(Combined_Data!C12 > 5000, Combined_Data!C12 - 5000, 0) -> 1126.3628 | D17: =IF(Combined_Data!D12 > 5000, Combined_Data!D12 - 5000, 0) -> 0 | E17: =IF(Combined_Data!E12 > 5000, Combined_Data!E12 - 5000, 0) -> 0 | F17: =IF(Combined_Data!F12 > 5000, Combined_Data!F12 - 5000, 0) -> 774.82511 | G17: =IF(Combined_Data!G12 > 5000, Combined_Data!G12 - 5000, 0) -> 0 | H17: =IF(Combined_Data!H12 > 5000, Combined_Data!H12 - 5000, 0) -> 1406.1825 | I17: =IF(Combined_Data!I12 > 5000, Combined_Data!I12 - 5000, 0) -> 0 | ... M17: =IF(Combined_Data!M12 > 5000, Combined_Data!M12 - 5000, 0) -> 0 | N17: =SUM(B17:M17) -> 15059.873
A18: SUB-475178203 | B18: =IF(Combined_Data!B13 > 5000, Combined_Data!B13 - 5000, 0) -> 11234.974 | C18: =IF(Combined_Data!C13 > 5000, Combined_Data!C13 - 5000, 0) -> 0 | D18: =IF(Combined_Data!D13 > 5000, Combined_Data!D13 - 5000, 0) -> 727.41509 | E18: =IF(Combined_Data!E13 > 5000, Combined_Data!E13 - 5000, 0) -> 0 | F18: =IF(Combined_Data!F13 > 5000, Combined_Data!F13 - 5000, 0) -> 2942.5962 | G18: =IF(Combined_Data!G13 > 5000, Combined_Data!G13 - 5000, 0) -> 6273.978 | H18: =IF(Combined_Data!H13 > 5000, Combined_Data!H13 - 5000, 0) -> 0 | I18: =IF(Combined_Data!I13 > 5000, Combined_Data!I13 - 5000, 0) -> 506.88135 | ... M18: =IF(Combined_Data!M13 > 5000, Combined_Data!M13 - 5000, 0) -> 0 | N18: =SUM(B18:M18) -> 23655.171
A19: SUB-384428935 | B19: =IF(Combined_Data!B14 > 5000, Combined_Data!B14 - 5000, 0) -> 11201.279 | C19: =IF(Combined_Data!C14 > 5000, Combined_Data!C14 - 5000, 0) -> 0 | D19: =IF(Combined_Data!D14 > 5000, Combined_Data!D14 - 5000, 0) -> 0 | E19: =IF(Combined_Data!E14 > 5000, Combined_Data!E14 - 5000, 0) -> 1880.8346 | F19: =IF(Combined_Data!F14 > 5000, Combined_Data!F14 - 5000, 0) -> 0 | G19: =IF(Combined_Data!G14 > 5000, Combined_Data!G14 - 5000, 0) -> 0 | H19: =IF(Combined_Data!H14 > 5000, Combined_Data!H14 - 5000, 0) -> 0 | I19: =IF(Combined_Data!I14 > 5000, Combined_Data!I14 - 5000, 0) -> 0 | ... M19: =IF(Combined_Data!M14 > 5000, Combined_Data!M14 - 5000, 0) -> 0 | N19: =SUM(B19:M19) -> 13082.114
... A1007: SUB-961271099 | B1007: =IF(Combined_Data!B1002 > 5000, Combined_Data!B1002 - 5000, 0) -> 0 | C1007: =IF(Combined_Data!C1002 > 5000, Combined_Data!C1002 - 5000, 0) -> 0 | D1007: =IF(Combined_Data!D1002 > 5000, Combined_Data!D1002 - 5000, 0) -> 0 | E1007: =IF(Combined_Data!E1002 > 5000, Combined_Data!E1002 - 5000, 0) -> 12077.526 | F1007: =IF(Combined_Data!F1002 > 5000, Combined_Data!F1002 - 5000, 0) -> 0 | G1007: =IF(Combined_Data!G1002 > 5000, Combined_Data!G1002 - 5000, 0) -> 0 | H1007: =IF(Combined_Data!H1002 > 5000, Combined_Data!H1002 - 5000, 0) -> 0 | I1007: =IF(Combined_Data!I1002 > 5000, Combined_Data!I1002 - 5000, 0) -> 0 | ... M1007: =IF(Combined_Data!M1002 > 5000, Combined_Data!M1002 - 5000, 0) -> 0 | N1007: =SUM(B1007:M1007) -> 12077.526

Sheet Excess data M Pack
A1: Excess pack details: | C1: 1GB for 5 Euros
C2: 5GB for 10 Euros
A3: No. of customers Change | C3: =COUNTIF(AF10:AF1009,">0") -> 1000
A4: No. of customer do not change | C4: =COUNTIF(AF10:AF1009,"<0") -> 0
A6: Total revenue | B6: =SUM(AF10:AF1009) -> 157120 | C6: Assuming that all customers would choose this package
D8: If the customers buy 1 GB extra for all their excess data | R8: If the customers buy 5 GB extra for all their excess data | AF8: Comparing both the packs which is cheaper for the customer
A9: Customer_ID | B9: Plan | D9: Excess_Data_jan | E9: Excess_Data_Feb | F9: Excess_Data_Mar | G9: Excess_Data_Apr | H9: Excess_Data_May | I9: Excess_Data_Jun | J9: Excess_Data_Jul | K9: Excess_Data_Aug | L9: Excess_Data_Sep | M9: Excess_Data_Oct | N9: Excess_Data_Nov | O9: Excess_Data_Dec | P9: Total_Excess_data_Purchaed | R9: Excess_Data_jan | S9: Excess_Data_Feb | T9: Excess_Data_Mar | U9: Excess_Data_Apr | V9: Excess_Data_May | W9: Excess_Data_Jun | X9: Excess_Data_Jul | Y9: Excess_Data_Aug | Z9: Excess_Data_Sep | AA9: Excess_Data_Oct | AB9: Excess_Data_Nov | AC9: Excess_Data_Dec | AD9: Total_Excess_data_Purchaed | AF9: Min of the 2 packs
A10: SUB-729143503 | B10: Reduced rate | D10: =CEILING('M Size Pack'!B8/1000,1) -> 24 | E10: =CEILING('M Size Pack'!C8/1000,1) -> 0 | F10: =CEILING('M Size Pack'!D8/1000,1) -> 0 | G10: =CEILING('M Size Pack'!E8/1000,1) -> 0 | H10: =CEILING('M Size Pack'!F8/1000,1) -> 0 | I10: =CEILING('M Size Pack'!G8/1000,1) -> 0 | J10: =CEILING('M Size Pack'!H8/1000,1) -> 5 | K10: =CEILING('M Size Pack'!I8/1000,1) -> 1 | ... O10: =CEILING('M Size Pack'!M8/1000,1) -> 0 | P10: =SUM(D10:O10)*5 -> 150 | R10: =CEILING('M Size Pack'!B8/5000,1) -> 5 | S10: =CEILING('M Size Pack'!C8/5000,1) -> 0 | T10: =CEILING('M Size Pack'!D8/5000,1) -> 0 | U10: =CEILING('M Size Pack'!E8/5000,1) -> 0 | V10: =CEILING('M Size Pack'!F8/5000,1) -> 0 | W10: =CEILING('M Size Pack'!G8/5000,1) -> 0 | X10: =CEILING('M Size Pack'!H8/5000,1) -> 1 | Y10: =CEILING('M Size Pack'!I8/5000,1) -> 1 | ... AC10: =CEILING('M Size Pack'!M8/5000,1) -> 0 | AD10: =SUM(R10:AC10)*10 -> 70 | AF10: =MIN(P10,AD10)+9.99*12 -> 189.88
A11: SUB-327259441 | B11: Reduced rate | D11: =CEILING('M Size Pack'!B9/1000,1) -> 23 | E11: =CEILING('M Size Pack'!C9/1000,1) -> 0 | F11: =CEILING('M Size Pack'!D9/1000,1) -> 0 | G11: =CEILING('M Size Pack'!E9/1000,1) -> 0 | H11: =CEILING('M Size Pack'!F9/1000,1) -> 0 | I11: =CEILING('M Size Pack'!G9/1000,1) -> 0 | J11: =CEILING('M Size Pack'!H9/1000,1) -> 0 | K11: =CEILING('M Size Pack'!I9/1000,1) -> 2 | ... O11: =CEILING('M Size Pack'!M9/1000,1) -> 0 | P11: =SUM(D11:O11)*5 -> 125 | R11: =CEILING('M Size Pack'!B9/5000,1) -> 5 | S11: =CEILING('M Size Pack'!C9/5000,1) -> 0 | T11: =CEILING('M Size Pack'!D9/5000,1) -> 0 | U11: =CEILING('M Size Pack'!E9/5000,1) -> 0 | V11: =CEILING('M Size Pack'!F9/5000,1) -> 0 | W11: =CEILING('M Size Pack'!G9/5000,1) -> 0 | X11: =CEILING('M Size Pack'!H9/5000,1) -> 0 | Y11: =CEILING('M Size Pack'!I9/5000,1) -> 1 | ... AC11: =CEILING('M Size Pack'!M9/5000,1) -> 0 | AD11: =SUM(R11:AC11)*10 -> 60 | AF11: =MIN(P11,AD11)+9.99*12 -> 179.88
