Workbook

Sheet Combined_Data
B1: Data (in Megabytes) | O1: Talktime (in Minutes) | AB1: Plan | AC1: Billing (in Euros)
A2: Customer_ID | B2: January_Data | C2: February_Data | D2: March_Data | E2: April_Data | F2: May_Data | G2: June_Data | H2: July_Data | I2: August_Data | J2: September_Data | K2: October_Data | L2: November_Data | M2: December_Data | N2: Total_Data_Usage | O2: January_Talktime | P2: February_Talktime | Q2: March_Talktime | R2: April_Talktime | S2: May_Talktime | T2: June_Talktime | U2: July_Talktime | V2: August_Talktime | W2: September_Talktime | X2: October_Talktime | Y2: November_Talktime | Z2: December_Talktime | AA2: Total_Talktime | AB2: Plan | AC2: January | AD2: February | AE2: March | AF2: April | AG2: May | AH2: June | AI2: July | AJ2: August | AK2: September | AL2: October | AM2: November | AN2: December | AO2: Total billing amount
A3: SUB-729143503 | B3: 28053.56 | C3: 2895.5485 | D3: 1351.6937 | E3: 3756.5219 | F3: 223.77361 | G3: 4012.203 | H3: 9166.6329 | I3: 5241.1959 | J3: 1596.4707 | K3: 961.4416 | L3: 0 | M3: 456.79371 | N3: =SUM(B3:M3) -> 57715.836 | O3: 0 | P3: 6.8243443 | Q3: 1.8348294 | R3: 0.13054242 | S3: 1.2363395 | T3: 5.2688933 | U3: 12.071899 | V3: 0 | W3: 9.526224 | X3: 9.9057137 | Y3: 10.55318 | Z3: 3.5335249 | AA3: =SUM(O3:Z3) -> 60.885491 | AB3: Reduced rate | AC3: 290.53 | AD3: 39.3 | AE3: 23.61 | AF3: 47.61 | AG3: 12.33 | AH3: 50.42 | AI3: 102.31 | AJ3: 62.41 | AK3: 26.46 | AL3: 20.11 | AM3: 10.54 | AN3: 14.76 | AO3: =SUM(AC3:AN3) -> 700.39
A4: SUB-327259441 | B4: 27981.652 | C4: 417.81517 | D4: 852.48705 | E4: 635.07388 | F4: 663.3152 | G4: 4986.3074 | H4: 1854.487 | I4: 6695.5891 | J4: 1891.9995 | K4: 887.893 | L4: 743.67274 | M4: 2697.434 | N4: =SUM(B4:M4) -> 50307.726 | O4: 3.0272902 | P4: 0 | Q4: 3.1933096 | R4: 13.726478 | S4: 2.7197324 | T4: 0.56202084 | U4: 1.6899206 | V4: 0.95496648 | W4: 2.2011679 | X4: 0.22231461 | Y4: 6.2190388 | Z4: 1.1186908 | AA4: =SUM(O4:Z4) -> 35.63493 | AB4: Reduced rate | AC4: 290.01 | AD4: 14.17 | AE4: 18.72 | AF4: 17.05 | AG4: 16.78 | AH4: 59.91 | AI4: 28.64 | AJ4: 77 | AK4: 29.06 | AL4: 18.92 | AM4: 17.78 | AN4: 37.07 | AO4: =SUM(AC4:AN4) -> 625.11
A5: SUB-720199369 | B5: 24077.595 | C5: 2040.3707 | D5: 697.99085 | E5: 2976.9148 | F5: 3284.5485 | G5: 0 | H5: 882.75571 | I5: 5062.1182 | J5: 1429.7181 | K5: 471.10911 | L5: 2549.1186 | M5: 347.76244 | N5: =SUM(B5:M5) -> 43820.002 | O5: 3.6953248 | P5: 5.7223518 | Q5: 1.9044145 | R5: 3.6303551 | S5: 2.6919952 | T5: 2.7536809 | U5: 7.5746851 | V5: 0 | W5: 1.6038991 | X5: 8.9788221 | Y5: 0.68691512 | Z5: 4.9413438 | AA5: =SUM(O5:Z5) -> 44.183788 | AB5: Reduced rate | AC5: 250.97 | AD5: 30.7 | AE5: 17.07 | AF5: 39.96 | AG5: 42.99 | AH5: 10.14 | AI5: 19.22 | AJ5: 60.62 | AK5: 24.39 | AL5: 15.16 | AM5: 35.54 | AN5: 13.72 | AO5: =SUM(AC5:AN5) -> 560.48
A6: SUB-115774364 | B6: 23074.756 | C6: 2785.5024 | D6: 284.71385 | E6: 3283.7711 | F6: 7459.8083 | G6: 3168.5675 | H6: 1907.4737 | I6: 339.31373 | J6: 2228.1186 | K6: 2686.797 | L6: 1170.1683 | M6: 7622.4986 | N6: =SUM(B6:M6) -> 56011.489 | O6: 1.0159856 | P6: 0.15372142 | Q6: 4.6900202 | R6: 4.5204292 | S6: 2.0791638 | T6: 6.6181137 | U6: 7.6565992 | V6: 5.3556575 | W6: 0 | X6: 3.3847081 | Y6: 3.4338634 | Z6: 4.6570532 | AA6: =SUM(O6:Z6) -> 43.565315 | AB6: Reduced rate | AC6: 240.84 | AD6: 37.9 | AE6: 13.09 | AF6: 43.08 | AG6: 84.74 | AH6: 42.03 | AI6: 29.47 | AJ6: 13.69 | AK6: 32.28 | AL6: 37.06 | AM6: 21.9 | AN6: 86.47 | AO6: =SUM(AC6:AN6) -> 682.55
A7: SUB-687511952 | B7: 22979.493 | C7: 2122.315 | D7: 876.83085 | E7: 5628.9233 | F7: 0 | G7: 1865.4922 | H7: 757.8359 | I7: 9671.7792 | J7: 2997.9954 | K7: 7828.6764 | L7: 1929.7365 | M7: 1642.5122 | N7: =SUM(B7:M7) -> 58301.59 | O7: 0 | P7: 0.28491236 | Q7: 2.3988806 | R7: 1.1966899 | S7: 1.2630293 | T7: 3.6460268 | U7: 1.5113669 | V7: 1.7826923 | W7: 6.1010391 | X7: 6.4017515 | Y7: 3.0686748 | Z7: 8.3819532 | AA7: =SUM(O7:Z7) -> 36.037017 | AB7: Reduced rate | AC7: 239.79 | AD7: 31.27 | AE7: 18.91 | AF7: 66.38 | AG7: 10.09 | AH7: 28.85 | AI7: 17.67 | AJ7: 106.81 | AK7: 40.32 | AL7: 88.63 | AM7: 29.49 | AN7: 26.87 | AO7: =SUM(AC7:AN7) -> 705.08
A8: SUB-884111294 | B8: 21172.886 | C8: 1523.6876 | D8: 1485.3058 | E8: 4193.1236 | F8: 1956.6123 | G8: 1901.2535 | H8: 3119.8269 | I8: 2239.8238 | J8: 5877.3904 | K8: 1648.9666 | L8: 9274.7754 | M8: 6059.3035 | N8: =SUM(B8:M8) -> 60452.956 | O8: 3.480402 | P8: 2.7555623 | Q8: 8.512322 | R8: 8.4869033 | S8: 0 | T8: 7.3523678 | U8: 2.5343937 | V8: 18.001429 | W8: 1.1814809 | X8: 18.746402 | Y8: 4.5426855 | Z8: 1.2377769 | AA8: =SUM(O8:Z8) -> 76.831726 | AB8: Reduced rate | AC8: 221.92 | AD8: 25.38 | AE8: 25.3 | AF8: 52.38 | AG8: 29.56 | AH8: 29.41 | AI8: 41.34 | AJ8: 33.34 | AK8: 68.87 | AL8: 27.43 | AM8: 102.99 | AN8: 70.69 | AO8: =SUM(AC8:AN8) -> 728.61
A9: SUB-754009185 | B9: 17677.832 | C9: 4761.3302 | D9: 3058.4981 | E9: 9399.811 | F9: 8675.879 | G9: 5734.8376 | H9: 3587.2216 | I9: 3564.4166 | J9: 1240.7474 | K9: 155.30631 | L9: 2065.3096 | M9: 2312.6221 | N9: =SUM(B9:M9) -> 62233.812 | O9: 4.6764258 | P9: 3.7891882 | Q9: 4.3049763 | R9: 5.2743849 | S9: 3.8110392 | T9: 0.29090471 | U9: 2.0522614 | V9: 4.2704145 | W9: 0.45728292 | X9: 1.6975736 | Y9: 1.5591213 | Z9: 2.8046566 | AA9: =SUM(O9:Z9) -> 34.988229 | AB9: Reduced rate | AC9: 187.02 | AD9: 57.81 | AE9: 40.83 | AF9: 104.29 | AG9: 96.95 | AH9: 67.39 | AI9: 46.02 | AJ9: 45.89 | AK9: 22.45 | AL9: 11.65 | AM9: 30.75 | AN9: 33.27 | AO9: =SUM(AC9:AN9) -> 744.32
A10: SUB-907933772 | B10: 17562.336 | C10: 1588.6695 | D10: 1873.9256 | E10: 12191.94 | F10: 3104.8013 | G10: 1559.3144 | H10: 4198.5673 | I10: 255.28364 | J10: 1706.0694 | K10: 506.10295 | L10: 317.99446 | M10: 0 | N10: =SUM(B10:M10) -> 44865.004 | O10: 0 | P10: 0.62814977 | Q10: 3.5003327 | R10: 3.3931231 | S10: 9.6599002 | T10: 2.2831001 | U10: 11.323904 | V10: 0.77391993 | W10: 0 | X10: 0 | Y10: 0 | Z10: 2.4815975 | AA10: =SUM(O10:Z10) -> 34.044027 | AB10: Reduced rate | AC10: 185.62 | AD10: 25.93 | AE10: 28.93 | AF10: 132.11 | AG10: 41.54 | AH10: 25.74 | AI10: 52.58 | AJ10: 12.6 | AK10: 27.06 | AL10: 15.06 | AM10: 13.17 | AN10: 10.14 | AO10: =SUM(AC10:AN10) -> 570.48
A11: SUB-219686190 | B11: 17310.819 | C11: 1600.9242 | D11: 4071.8053 | E11: 808.60022 | F11: 208.4777 | G11: 6817.1882 | H11: 1511.4908 | I11: 1614.1089 | J11: 1723.2336 | K11: 11608.721 | L11: 0 | M11: 5663.6196 | N11: =SUM(B11:M11) -> 52938.988 | O11: 0.16695997 | P11: 1.3625016 | Q11: 5.6891728 | R11: 5.6100635 | S11: 1.8632851 | T11: 0 | U11: 2.7344741 | V11: 2.7288639 | W11: 10.096708 | X11: 4.570316 | Y11: 0.73125341 | Z11: 3.9632105 | AA11: =SUM(O11:Z11) -> 39.516809 | AB11: Reduced rate | AC11: 183.15 | AD11: 26.1 | AE11: 51.01 | AF11: 18.38 | AG11: 12.18 | AH11: 78.17 | AI11: 25.26 | AJ11: 26.29 | AK11: 27.78 | AL11: 126.33 | AM11: 10.04 | AN11: 66.83 | AO11: =SUM(AC11:AN11) -> 651.52
A12: SUB-275406642 | B12: 16752.503 | C12: 6126.3628 | D12: 2972.6152 | E12: 4473.5263 | F12: 5774.8251 | G12: 2388.7042 | H12: 6406.1825 | I12: 1414.0145 | J12: 1243.7208 | K12: 2317.0722 | L12: 4556.8202 | M12: 4306.3377 | N12: =SUM(B12:M12) -> 58732.684 | O12: 6.9119753 | P12: 0.18325476 | Q12: 5.0499693 | R12: 3.018949 | S12: 11.830532 | T12: 0.1598578 | U12: 2.7107988 | V12: 9.711794 | W12: 0.44653473 | X12: 12.236804 | Y12: 3.7763513 | Z12: 1.7315306 | AA12: =SUM(O12:Z12) -> 57.768352 | AB12: Reduced rate | AC12: 177.87 | AD12: 71.31 | AE12: 40.02 | AF12: 54.93 | AG12: 68.34 | AH12: 33.93 | AI12: 74.21 | AJ12: 24.64 | AK12: 22.48 | AL12: 33.82 | AM12: 55.76 | AN12: 53.16 | AO12: =SUM(AC12:AN12) -> 710.47
A13: SUB-475178203 | B13: 16234.974 | C13: 3934.7617 | D13: 5727.4151 | E13: 0 | F13: 7942.5962 | G13: 11273.978 | H13: 2245.1036 | I13: 5506.8814 | J13: 2619.9452 | K13: 631.70776 | L13: 6969.3265 | M13: 3442.1968 | N13: =SUM(B13:M13) -> 66528.886 | O13: 0.10338663 | P13: 3.6698164 | Q13: 0 | R13: 10.17963 | S13: 6.6749883 | T13: 5.0695154 | U13: 1.0149742 | V13: 7.4529844 | W13: 7.397938 | X13: 5.9770251 | Y13: 1.926056 | Z13: 4.0583869 | AA13: =SUM(O13:Z13) -> 53.524702 | AB13: Reduced rate | AC13: 172.39 | AD13: 49.54 | AE13: 67.27 | AF13: 10.54 | AG13: 89.77 | AH13: 123.03 | AI13: 32.55 | AJ13: 65.46 | AK13: 36.59 | AL13: 16.61 | AM13: 79.79 | AN13: 44.67 | AO13: =SUM(AC13:AN13) -> 788.21
A14: SUB-384428935 | B14: 16201.279 | C14: 1976.3677 | D14: 1334.0698 | E14: 6880.8346 | F14: 2098.5512 | G14: 1613.6047 | H14: 1941.8694 | I14: 3510.1076 | J14: 0 | K14: 1530.7356 | L14: 2422.2141 | M14: 1134.3007 | N14: =SUM(B14:M14) -> 40643.934 | O14: 2.2438026 | P14: 20.086245 | Q14: 0 | R14: 2.9771223 | S14: 11.89283 | T14: 0.27558812 | U14: 14.22914 | V14: 11.30351 | W14: 8.9568708 | X14: 2.5598834 | Y14: 5.6794312 | Z14: 6.6390676 | AA14: =SUM(O14:Z14) -> 86.843491 | AB14: Reduced rate | AC14: 172.16 | AD14: 30.81 | AE14: 23.34 | AF14: 78.95 | AG14: 31.58 | AH14: 26.18 | AI14: 30.16 | AJ14: 45.7 | AK14: 10.44 | AL14: 25.45 | AM14: 34.52 | AN14: 21.69 | AO14: =SUM(AC14:AN14) -> 530.98
... A893: SUB-794177654 | B893: 9.9468182 | C893: 3853.098 | D893: 2169.3201 | E893: 3469.7822 | F893: 4577.7392 | G893: 4563.6135 | H893: 3504.2403 | I893: 3348.378 | J893: 787.56729 | K893: 886.27349 | L893: 3231.5868 | M893: 2240.2039 | N893: =SUM(B893:M893) -> 32641.75 | O893: 2.2824462 | P893: 2.7843054 | Q893: 3.4749852 | R893: 3.2232285 | S893: 2.3887401 | T893: 6.5501937 | U893: 4.0512609 | V893: 0 | W893: 2.0447171 | X893: 5.6797415 | Y893: 2.6602769 | Z893: 3.6138055 | AA893: =SUM(O893:Z893) -> 38.753701 | AB893: Pay-as-you-go | AC893: 0.47 | AD893: 77.35 | AE893: 43.76 | AF893: 69.76 | AG893: 91.83 | AH893: 91.91 | AI893: 70.55 | AJ893: 66.98 | AK893: 16.03 | AL893: 18.28 | AM893: 64.91 | AN893: 45.18 | AO893: =SUM(AC893:AN893) -> 657.01
A894: SUB-928511911 | B894: 0 | C894: 12943.116 | D894: 6297.5226 | E894: 0 | F894: 28266.985 | G894: 2921.4545 | H894: 6336.0007 | I894: 216.28226 | J894: 1422.9196 | K894: 4797.8424 | L894: 286.28697 | M894: 2230.0758 | N894: =SUM(B894:M894) -> 65718.486 | O894: 0 | P894: 3.143746 | Q894: 10.909133 | R894: 4.6205672 | S894: 4.4109608 | T894: 3.5561012 | U894: 1.3723442 | V894: 3.6591779 | W894: 4.0311417 | X894: 1.8237247 | Y894: 1.6657105 | Z894: 2.318 | AA894: =SUM(O894:Z894) -> 41.510607 | AB894: Pay-as-you-go | AD894: 259.24 | AE894: 126.95 | AF894: 0.45 | AG894: 565.79 | AH894: 58.8 | AI894: 126.92 | AJ894: 4.7 | AK894: 28.91 | AL894: 96.14 | AM894: 5.92 | AN894: 44.89 | AO894: =SUM(AC894:AN894) -> 1318.71
A895: SUB-414114481 | B895: 0 | C895: 8454.2086 | D895: 10680.127 | E895: 16875.697 | F895: 6880.6843 | G895: 611.32179 | H895: 4752.2527 | I895: 516.2456 | J895: 7758.3414 | K895: 1042.6837 | L895: 517.05686 | M895: 8528.1632 | N895: =SUM(B895:M895) -> 66616.782 | O895: 2.9461809 | P895: 16.467007 | Q895: 4.0925789 | R895: 0.47543171 | S895: 0.55776133 | T895: 2.6805405 | U895: 0 | V895: 0 | W895: 1.5391586 | X895: 2.926375 | Y895: 2.4096702 | Z895: 1.1639022 | AA895: =SUM(O895:Z895) -> 35.258606 | AB895: Pay-as-you-go | AC895: 0.27 | AD895: 170.63 | AE895: 214.07 | AF895: 337.61 | AG895: 137.71 | AH895: 12.51 | AI895: 95.06 | AJ895: 10.34 | AK895: 155.36 | AL895: 21.13 | AM895: 10.63 | AN895: 170.76 | AO895: =SUM(AC895:AN895) -> 1336.08
A896: SUB-996400695 | B896: 0 | C896: 6783.8768 | D896: 1702.1 | E896: 1356.2098 | F896: 3224.3312 | G896: 2121.5025 | H896: 3375.4283 | I896: 3243.749 | J896: 4071.1388 | K896: 6329.0776 | L896: 886.36755 | M896: 1918.468 | N896: =SUM(B896:M896) -> 35012.25 | O896: 0 | P896: 0.85333558 | Q896: 14.725982 | R896: 0.96556171 | S896: 4.0969138 | T896: 0.93532242 | U896: 6.2974214 | V896: 0 | W896: 14.425496 | X896: 1.3316665 | Y896: 0 | Z896: 0 | AA896: =SUM(O896:Z896) -> 43.631699 | AB896: Pay-as-you-go | AD896: 135.77 | AE896: 35.41 | AF896: 27.23 | AG896: 64.95 | AH896: 42.53 | AI896: 68.15 | AJ896: 64.88 | AK896: 82.79 | AL896: 126.78 | AM896: 17.74 | AN896: 38.38 | AO896: =SUM(AC896:AN896) -> 704.61
A897: SUB-137805061 | B897: 0 | C897: 5484.7744 | D897: 0 | E897: 1240.4971 | F897: 3882.5124 | G897: 3913.9764 | H897: 5068.3519 | I897: 2804.4772 | J897: 2661.8752 | K897: 8753.3647 | L897: 2345.7654 | M897: 2.2910935 | N897: =SUM(B897:M897) -> 36157.886 | O897: 0 | P897: 0.3594828 | Q897: 10.165985 | R897: 1.0537743 | S897: 3.8019961 | T897: 5.2162518 | U897: 0.48317986 | V897: 15.445314 | W897: 13.465932 | X897: 2.6964304 | Y897: 3.317922 | Z897: 0.34897139 | AA897: =SUM(O897:Z897) -> 56.35524 | AB897: Pay-as-you-go | AD897: 109.79 | AE897: 0.99 | AF897: 25 | AG897: 78.02 | AH897: 78.82 | AI897: 101.47 | AJ897: 57.54 | AK897: 54.5 | AL897: 175.35 | AM897: 47.28 | AN897: 0.15 | AO897: =SUM(AC897:AN897) -> 728.91
A898: SUB-474945743 | B898: 0 | C898: 5079.4745 | D898: 3051.7562 | E898: 4641.0843 | F898: 386.82587 | G898: 11215.752 | H898: 0 | I898: 1680.3037 | J898: 3298.6346 | K898: 0 | L898: 332.59172 | M898: 527.06218 | N898: =SUM(B898:M898) -> 30213.485 | O898: 6.0295045 | P898: 1.9204556 | Q898: 3.9256962 | R898: 6.2211833 | S898: 0.26186595 | T898: 13.566048 | U898: 7.3645143 | V898: 2.2805143 | W898: 1.5158335 | X898: 0 | Y898: 1.7242916 | Z898: 7.1470572 | AA898: =SUM(O898:Z898) -> 51.956964 | AB898: Pay-as-you-go | AC898: 0.63 | AD898: 101.78 | AE898: 61.4 | AF898: 93.47 | AG898: 7.83 | AH898: 225.58 | AI898: 0.72 | AJ898: 33.89 | AK898: 66.16 | AL898: 0 | AM898: 6.84 | AN898: 11.28 | AO898: =SUM(AC898:AN898) -> 609.58
A899: SUB-320112847 | B899: 0 | C899: 5014.25 | D899: 739.38302 | E899: 3380.8393 | F899: 718.5235 | G899: 2377.1628 | H899: 6412.137 | I899: 5459.3947 | J899: 908.63328 | K899: 2807.3975 | L899: 2701.4436 | M899: 877.34389 | N899: =SUM(B899:M899) -> 31396.509 | O899: 0.33632751 | P899: 0 | Q899: 2.8809274 | R899: 4.4286643 | S899: 4.0173057 | T899: 0 | U899: 13.658446 | V899: 0 | W899: 1.4127249 | X899: 0 | Y899: 3.1925685 | Z899: 11.94017 | AA899: =SUM(O899:Z899) -> 41.867134 | AB899: Pay-as-you-go | AC899: 0.09 | AD899: 100.3 | AE899: 15.07 | AF899: 68.07 | AG899: 14.83 | AH899: 47.56 | AI899: 129.52 | AJ899: 109.2 | AK899: 18.36 | AL899: 56.16 | AM899: 54.4 | AN899: 18.64 | AO899: =SUM(AC899:AN899) -> 632.2
A900: SUB-309284306 | B900: 0 | C900: 4804.5749 | D900: 2451.5004 | E900: 0 | F900: 5312.3956 | G900: 4973.7967 | H900: 1409.7628 | I900: 531.20554 | J900: 1428.6927 | K900: 2789.2733 | L900: 7452.1114 | M900: 1635.8805 | N900: =SUM(B900:M900) -> 32789.194 | O900: 3.5190982 | P900: 7.8010408 | Q900: 2.5400861 | R900: 2.4616911 | S900: 4.4692417 | T900: 0.81136147 | U900: 2.9430812 | V900: 6.4497894 | W900: 2.0919546 | X900: 4.9004954 | Y900: 3.2855948 | Z900: 0 | AA900: =SUM(O900:Z900) -> 41.273435 | AB900: Pay-as-you-go | AC900: 0.36 | AD900: 96.82 | AE900: 49.31 | AF900: 0.27 | AG900: 106.71 | AH900: 99.57 | AI900: 28.47 | AJ900: 11.27 | AK900: 28.85 | AL900: 56.25 | AM900: 149.42 | AN900: 32.72 | AO900: =SUM(AC900:AN900) -> 660.02
A901: SUB-314510883 | B901: 0 | C901: 4620.9847 | D901: 1886.8344 | E901: 0 | F901: 1444.3624 | G901: 0 | H901: 5514.5869 | I901: 4785.3439 | J901: 7557.7599 | K901: 2455.76 | L901: 809.99158 | M901: 352.25 | N901: =SUM(B901:M901) -> 29427.874 | O901: 1.3009787 | P901: 3.1672884 | Q901: 4.1297905 | R901: 2.6446201 | S901: 3.3277668 | T901: 0 | U901: 2.3122589 | V901: 1.5170059 | W901: 12.619266 | X901: 7.1188983 | Y901: 12.892263 | Z901: 0 | AA901: =SUM(O901:Z901) -> 51.030138 | AB901: Pay-as-you-go | AC901: 0.18 | AD901: 92.78 | AE901: 38.19 | AF901: 0.27 | AG901: 29.26 | AH901: 0 | AI901: 110.57 | AJ901: 95.9 | AK901: 152.33 | AL901: 49.84 | AM901: 17.37 | AN901: 7.06 | AO901: =SUM(AC901:AN901) -> 593.75
A902: SUB-890910481 | B902: 0 | C902: 4605.8996 | D902: 3328.3965 | E902: 3228.9678 | F902: 1212.7425 | G902: 227.11129 | H902: 5438.5608 | I902: 7126.2902 | J902: 2028.2079 | K902: 926.65434 | L902: 0 | M902: 4875.7541 | N902: =SUM(B902:M902) -> 32998.585 | O902: 6.2240737 | P902: 5.1990476 | Q902: 0 | R902: 3.7238477 | S902: 2.0036781 | T902: 0 | U902: 8.2255529 | V902: 0 | W902: 1.0910262 | X902: 11.478312 | Y902: 1.5648237 | Z902: 16.801943 | AA902: =SUM(O902:Z902) -> 56.312305 | AB902: Pay-as-you-go | AC902: 0.63 | AD902: 92.66 | AE902: 66.58 | AF902: 64.94 | AG902: 24.53 | AH902: 4.56 | AI902: 109.59 | AJ902: 142.54 | AK902: 40.76 | AL902: 19.62 | AM902: 0.18 | AN902: 99.05 | AO902: =SUM(AC902:AN902) -> 665.64
A903: SUB-122771504 | B903: 0 | C903: 3664.2394 | D903: 8411.2078 | E903: 454.06967 | F903: 1633.6899 | G903: 5542.6689 | H903: 1794.0526 | I903: 0 | J903: 1216.3224 | K903: 1436.7165 | L903: 7041.9234 | M903: 2812.2744 | N903: =SUM(B903:M903) -> 34007.165 | O903: 8.4321304 | P903: 2.1134551 | Q903: 0 | R903: 1.224747 | S903: 0.026622636 | T903: 4.0980804 | U903: 1.1773012 | V903: 0 | W903: 3.4528805 | X903: 0.85734524 | Y903: 2.5651186 | Z903: 3.4059173 | AA903: =SUM(O903:Z903) -> 27.353598 | AB903: Pay-as-you-go | AC903: 0.81 | AD903: 73.57 | AE903: 168.24 | AF903: 9.28 | AG903: 32.77 | AH903: 111.31 | AI903: 36.08 | AJ903: 0 | AK903: 24.7 | AL903: 28.83 | AM903: 141.11 | AN903: 56.62 | AO903: =SUM(AC903:AN903) -> 683.32
A904: SUB-907081959 | B904: 0 | C904: 3662.5494 | D904: 3229.8721 | E904: 7818.6524 | F904: 50.22897 | G904: 1620.0292 | H904: 602.43523 | I904: 11646.178 | J904: 1330.8063 | K904: 299.56011 | L904: 2454.4619 | M904: 2452.6881 | N904: =SUM(B904:M904) -> 35167.462 | O904: 8.4747469 | P904: 0.9824248 | Q904: 4.1397984 | R904: 1.9751674 | S904: 0 | T904: 9.1914476 | U904: 7.867708 | V904: 4.6662279 | W904: 8.3235229 | X904: 8.951715 | Y904: 4.1383622 | Z904: 5.7404462 | AA904: =SUM(O904:Z904) -> 64.451567 | AB904: Pay-as-you-go | AC904: 0.81 | AD904: 73.35 | AE904: 65.05 | AF904: 156.56 | AG904: 1.02 | AH904: 33.32 | AI904: 12.78 | AJ904: 233.39 | AK904: 27.43 | AL904: 6.81 | AM904: 49.55 | AN904: 49.6 | AO904: =SUM(AC904:AN904) -> 709.67
A905: SUB-207733458 | B905: 0 | C905: 3422.9037 | D905: 3194.2143 | E905: 925.21193 | F905: 6027.4984 | G905: 147.44332 | H905: 5406.6288 | I905: 793.94908 | J905: 4140.8474 | K905: 993.63492 | L905: 599.49863 | M905: 4854.5732 | N905: =SUM(B905:M905) -> 30506.404 | O905: 3.1652242 | P905: 6.637187 | Q905: 0.31920959 | R905: 4.0460599 | S905: 4.3977899 | T905: 0 | U905: 3.6307329 | V905: 5.7180518 | W905: 2.586169 | X905: 0 | Y905: 0 | Z905: 1.8402756 | AA905: =SUM(O905:Z905) -> 32.3407 | AB905: Pay-as-you-go | AC905: 0.36 | AD905: 69.09 | AE905: 63.99 | AF905: 18.97 | AG905: 121.01 | AH905: 2.96 | AI905: 108.5 | AJ905: 16.42 | AK905: 83.09 | AL905: 19.88 | AM905: 12 | AN905: 97.28 | AO905: =SUM(AC905:AN905) -> 613.55
A906: SUB-742447206 | B906: 0 | C906: 3354.923 | D906: 2162.1738 | E906: 5881.6181 | F906: 3083.3459 | G906: 6987.3869 | H906: 675.44656 | I906: 3188.7628 | J906: 953.43203 | K906: 1651.894 | L906: 7813.6043 | M906: 1368.259 | N906: =SUM(B906:M906) -> 37120.846 | O906: 6.8847197 | P906: 10.097849 | Q906: 2.0008783 | R906: 1.7907601 | S906: 2.4606165 | T906: 8.2887288 | U906: 0.7105894 | V906: 0.59352954 | W906: 7.1342775 | X906: 0.44956576 | Y906: 4.1726052 | Z906: 0.69299067 | AA906: =SUM(O906:Z906) -> 45.277111 | AB906: Pay-as-you-go | AC906: 0.63 | AD906: 68.09 | AE906: 43.53 | AF906: 117.82 | AG906: 61.95 | AH906: 140.57 | AI906: 13.61 | AJ906: 63.87 | AK906: 19.8 | AL906: 33.13 | AM906: 156.73 | AN906: 27.47 | AO906: =SUM(AC906:AN906) -> 747.2
A907: SUB-425606111 | B907: 0 | C907: 3178.4601 | D907: 8157.9796 | E907: 489.22732 | F907: 2367.0085 | G907: 5264.7096 | H907: 636.72291 | I907: 0 | J907: 2523.7437 | K907: 5092.2597 | L907: 169.45737 | M907: 6130.407 | N907: =SUM(B907:M907) -> 34009.976 | O907: 4.4804098 | P907: 6.9490902 | Q907: 8.8145112 | R907: 6.3976384 | S907: 1.093635 | T907: 2.4004427 | U907: 2.0596671 | V907: 4.5974445 | W907: 1.9828325 | X907: 3.2631922 | Y907: 1.1317575 | Z907: 0.6316402 | AA907: =SUM(O907:Z907) -> 43.802261 | AB907: Pay-as-you-go | AC907: 0.45 | AD907: 64.21 | AE907: 163.97 | AF907: 10.43 | AG907: 47.54 | AH907: 105.57 | AI907: 13.01 | AJ907: 0.45 | AK907: 50.66 | AL907: 102.22 | AM907: 3.58 | AN907: 122.71 | AO907: =SUM(AC907:AN907) -> 684.8
A908: SUB-545952317 | B908: 0 | C908: 2740.1332 | D908: 2012.966 | E908: 1934.6194 | F908: 5212.4989 | G908: 1487.2239 | H908: 7323.9396 | I908: 0 | J908: 1773.8144 | K908: 4350.4284 | L908: 2431.9344 | M908: 0 | N908: =SUM(B908:M908) -> 29267.558 | O908: 9.0067892 | P908: 6.1576562 | Q908: 6.5630083 | R908: 4.3489986 | S908: 0.9215398 | T908: 4.7684233 | U908: 0.53045653 | V908: 3.6569762 | W908: 0 | X908: 6.264829 | Y908: 0 | Z908: 10.19993 | AA908: =SUM(O908:Z908) -> 52.418608 | AB908: Pay-as-you-go | AC908: 0.9 | AD908: 55.45 | AE908: 40.89 | AF908: 39.15 | AG908: 104.35 | AH908: 30.21 | AI908: 146.57 | AJ908: 0.36 | AK908: 35.48 | AL908: 87.65 | AM908: 48.64 | AN908: 0.99 | AO908: =SUM(AC908:AN908) -> 590.64
A909: SUB-921245657 | B909: 0 | C909: 2500.5925 | D909: 1211.2454 | E909: 2888.3056 | F909: 0 | G909: 3454.4579 | H909: 4242.7551 | I909: 1785.7606 | J909: 1281.8911 | K909: 0 | L909: 381.16362 | M909: 2290.5001 | N909: =SUM(B909:M909) -> 20036.672 | O909: 11.137581 | P909: 1.9751824 | Q909: 14.763221 | R909: 1.747871 | S909: 11.010165 | T909: 0.26696745 | U909: 6.5584539 | V909: 2.1556627 | W909: 3.3403359 | X909: 0.79504318 | Y909: 5.3994002 | Z909: 0 | AA909: =SUM(O909:Z909) -> 59.149883 | AB909: Pay-as-you-go | AC909: 1.08 | AD909: 50.2 | AE909: 25.59 | AF909: 57.96 | AG909: 1.08 | AH909: 69.19 | AI909: 85.49 | AJ909: 35.99 | AK909: 26 | AL909: 0.09 | AM909: 8.18 | AN909: 45.82 | AO909: =SUM(AC909:AN909) -> 406.67
... A949: SUB-984807958 | B949: 0 | C949: 5769.4768 | D949: 5927.6482 | E949: 4890.5559 | F949: 382.82538 | G949: 4217.6234 | H949: 1305.2195 | I949: 2043.3128 | J949: 754.4429 | K949: 9398.8742 | L949: 942.14411 | M949: 2971.3993 | N949: =SUM(B949:M949) -> 38603.523 | O949: 1.4061369 | P949: 2.4444008 | Q949: 6.1520597 | R949: 9.2948668 | S949: 9.0367289 | T949: 5.3916786 | U949: 8.8367753 | V949: 1.9468334 | W949: 0.35880581 | X949: 1.4556245 | Y949: 0.90654344 | Z949: 0.73464789 | AA949: =SUM(O949:Z949) -> 47.965102 | AB949: Reduced rate | AC949: 10.09 | AD949: 67.84 | AE949: 69.62 | AF949: 59.4 | AG949: 14.32 | AH949: 52.47 | AI949: 23.5 | AJ949: 30.53 | AK949: 17.59 | AL949: 104.08 | AM949: 19.47 | AN949: 39.76 | AO949: =SUM(AC949:AN949) -> 508.67
A950: SUB-538425944 | C950: 5504.66 | D950: 2570.6549 | E950: 3231.9962 | F950: 980.81565 | G950: 5089.2196 | H950: 0 | I950: 584.03414 | J950: 4044.8954 | K950: 8117.0924 | L950: 262.86767 | M950: 3653.2445 | N950: =SUM(B950:M950) -> 34039.48 | P950: 0 | Q950: 0 | R950: 3.3525874 | S950: 1.8459314 | T950: 1.1728517 | U950: 2.8181484 | V950: 1.9746115 | W950: 2.2603126 | X950: 0.41015734 | Y950: 14.058739 | Z950: 3.7040511 | AA950: =SUM(O950:Z950) -> 31.59739 | AB950: Pay-as-you-go | AD950: 110.1 | AE950: 51.42 | AF950: 65 | AG950: 19.8 | AH950: 101.98 | AI950: 0.27 | AJ950: 11.88 | AK950: 81.17 | AL950: 162.45 | AM950: 6.61 | AN950: 73.44 | AO950: =SUM(AC950:AN950) -> 684.12
A951: SUB-460053662 | C951: 5208.7135 | D951: 1337.139 | E951: 2371.1417 | F951: 2223.905 | G951: 2951.7348 | H951: 401.81233 | I951: 785.06156 | J951: 3534.9556 | K951: 2500.7237 | L951: 3291.6458 | M951: 3384.3168 | N951: =SUM(B951:M951) -> 27991.15 | P951: 0.41467863 | Q951: 3.4933205 | R951: 0.31359203 | S951: 3.2341818 | T951: 6.6733167 | U951: 0.84185885 | V951: 4.1716722 | W951: 5.4395061 | X951: 0 | Y951: 5.5492368 | Z951: 4.156887 | AA951: =SUM(O951:Z951) -> 34.288251 | AB951: Pay-as-you-go | AD951: 104.27 | AE951: 27.12 | AF951: 47.53 | AG951: 44.84 | AH951: 59.67 | AI951: 8.13 | AJ951: 16.17 | AK951: 71.24 | AL951: 50.02 | AM951: 66.38 | AN951: 68.15 | AO951: =SUM(AC951:AN951) -> 563.52
A952: SUB-719844185 | C952: 5014.0863 | D952: 3215.6057 | E952: 159.10658 | F952: 1128.1899 | G952: 4426.5064 | H952: 595.37432 | I952: 548.63894 | J952: 2367.3918 | K952: 6626.3281 | L952: 1109.3063 | M952: 724.74798 | N952: =SUM(B952:M952) -> 25915.282 | P952: 1.0889759 | Q952: 1.4563872 | R952: 0 | S952: 2.4493563 | T952: 6.1765685 | U952: 11.821107 | V952: 2.3293418 | W952: 3.0301253 | X952: 0.69447143 | Y952: 3.5459295 | Z952: 1.5392782 | AA952: =SUM(O952:Z952) -> 34.131541 | AB952: Pay-as-you-go | AD952: 100.48 | AE952: 64.5 | AF952: 3.2 | AG952: 22.85 | AH952: 89.17 | AI952: 13 | AJ952: 11.25 | AK952: 47.72 | AL952: 132.63 | AM952: 22.56 | AN952: 14.68 | AO952: =SUM(AC952:AN952) -> 522.04
A953: SUB-571036263 | C953: 4180.8799 | D953: 2279.2318 | E953: 1075.7987 | F953: 1523.3522 | G953: 1439.1578 | H953: 661.56518 | I953: 5161.8154 | J953: 4260.4521 | K953: 1780.7454 | L953: 2335.6094 | M953: 1876.9912 | N953: =SUM(B953:M953) -> 26575.599 | P953: 0.046755479 | Q953: 17.231388 | R953: 0.3129928 | S953: 6.6335265 | T953: 3.1937214 | U953: 4.6393141 | V953: 2.4992258 | W953: 1.2565445 | X953: 9.5745005 | Y953: 11.077008 | Z953: 8.0202037 | AA953: =SUM(O953:Z953) -> 64.485181 | AB953: Pay-as-you-go | AD953: 83.71 | AE953: 47.22 | AF953: 21.61 | AG953: 31.11 | AH953: 29.16 | AI953: 13.69 | AJ953: 103.51 | AK953: 85.4 | AL953: 36.52 | AM953: 47.8 | AN953: 38.35 | AO953: =SUM(AC953:AN953) -> 538.08
A954: SUB-720331552 | C954: 3986.9135 | D954: 6238.2232 | E954: 2244.9442 | F954: 1717.2879 | G954: 339.7041 | H954: 5451.0595 | I954: 596.1593 | J954: 2185.4463 | K954: 1056.8739 | L954: 3156.7187 | M954: 4557.2186 | N954: =SUM(B954:M954) -> 31530.549 | P954: 8.0788459 | Q954: 4.1142585 | R954: 8.0662554 | S954: 0 | T954: 14.411465 | U954: 4.8176333 | V954: 0.18427497 | W954: 5.6750868 | X954: 0.17750264 | Y954: 7.4128378 | Z954: 0.43947722 | AA954: =SUM(O954:Z954) -> 53.377637 | AB954: Pay-as-you-go | AD954: 80.55 | AE954: 125.23 | AF954: 45.71 | AG954: 34.36 | AH954: 8.15 | AI954: 109.49 | AJ954: 12.03 | AK954: 44.26 | AL954: 21.23 | AM954: 63.86 | AN954: 91.25 | AO954: =SUM(AC954:AN954) -> 636.12
A955: SUB-653039003 | C955: 3189.7245 | D955: 0 | E955: 112.8603 | F955: 2318.5949 | G955: 982.75861 | H955: 6309.3869 | I955: 1647.3242 | J955: 14310.024 | K955: 4528.1777 | L955: 0 | M955: 1466.6296 | N955: =SUM(B955:M955) -> 34865.48 | P955: 1.1055033 | Q955: 1.0292283 | R955: 0.93950206 | S955: 4.580459 | T955: 2.0656366 | U955: 10.435644 | V955: 3.3742802 | W955: 19.297175 | X955: 8.8811675 | Y955: 0.74800421 | Z955: 9.9542266 | AA955: =SUM(O955:Z955) -> 62.410827 | AB955: Pay-as-you-go | AD955: 63.98 | AE955: 0.18 | AF955: 2.35 | AG955: 46.83 | AH955: 19.93 | AI955: 127.19 | AJ955: 33.32 | AK955: 288.02 | AL955: 91.39 | AM955: 0.09 | AN955: 30.24 | AO955: =SUM(AC955:AN955) -> 703.52
A956: SUB-975460557 | C956: 3175.6351 | D956: 3969.0512 | E956: 3242.8825 | F956: 1650.7161 | G956: 882.34254 | H956: 1825.312 | I956: 1533.6087 | J956: 0 | K956: 6793.5769 | L956: 1678.0995 | M956: 9342.7452 | N956: =SUM(B956:M956) -> 34093.97 | P956: 0 | Q956: 9.6370732 | R956: 10.64425 | S956: 0 | T956: 0.081302693 | U956: 5.4159945 | V956: 5.9521681 | W956: 1.6006319 | X956: 2.1384092 | Y956: 3.3199289 | Z956: 1.6563321 | AA956: =SUM(O956:Z956) -> 40.446091 | AB956: Pay-as-you-go | AD956: 63.52 | AE956: 80.3 | AF956: 65.85 | AG956: 33.02 | AH956: 17.75 | AI956: 37.06 | AJ956: 31.22 | AK956: 0.18 | AL956: 136.15 | AM956: 33.94 | AN956: 187.04 | AO956: =SUM(AC956:AN956) -> 686.03
A957: SUB-212766319 | C957: 2664.0766 | D957: 3063.4038 | E957: 1876.2939 | F957: 3048.4531 | G957: 704.35463 | H957: 1069.3947 | I957: 2704.1742 | J957: 7947.6785 | K957: 718.9787 | L957: 2939.4832 | M957: 329.93919 | N957: =SUM(B957:M957) -> 27066.231 | P957: 0 | Q957: 0.1572559 | R957: 0 | S957: 0.86068745 | T957: 7.3222978 | U957: 0 | V957: 5.7821693 | W957: 0.74302977 | X957: 8.9192903 | Y957: 2.734986 | Z957: 0.53455324 | AA957: =SUM(O957:Z957) -> 27.05427 | AB957: Pay-as-you-go | AD957: 53.3 | AE957: 61.37 | AF957: 37.54 | AG957: 61.07 | AH957: 14.82 | AI957: 21.4 | AJ957: 54.64 | AK957: 159.05 | AL957: 15.19 | AM957: 59.07 | AN957: 6.69 | AO957: =SUM(AC957:AN957) -> 544.14
...

Sheet Pay as you go
B1: Data (rounded up to MB) | O1: Talktime (rounded up to mins) | AC1: Billing (in euros)
A2: Customer_ID | B2: January_Data | C2: February_Data | D2: March_Data | E2: April_Data | F2: May_Data | G2: June_Data | H2: July_Data | I2: August_Data | J2: September_Data | K2: October_Data | L2: November_Data | M2: December_Data | N2: Total_Data_Usage | O2: January_Talktime | P2: February_Talktime | Q2: March_Talktime | R2: April_Talktime | S2: May_Talktime | T2: June_Talktime | U2: July_Talktime | V2: August_Talktime | W2: September_Talktime | X2: October_Talktime | Y2: November_Talktime | Z2: December_Talktime | AA2: Total_Talktime | AB2: Plan | AC2: January | AD2: February | AE2: March | AF2: April | AG2: May | AH2: June | AI2: July | AJ2: August | AK2: September | AL2: October | AM2: November | AN2: December | AO2: Total billing amount
A3: SUB-650580748 | B3: 14824 | C3: 659 | D3: 2248 | E3: 28 | F3: 897 | G3: 4226 | H3: 825 | I3: 4670 | J3: 3359 | K3: 1240 | L3: 2222 | M3: 0 | N3: =SUM(B3:M3) -> 35198 | O3: 2 | P3: 3 | Q3: 1 | R3: 2 | S3: 1 | T3: 10 | U3: 5 | V3: 3 | W3: 1 | X3: 17 | Y3: 4 | Z3: 1 | AA3: =SUM(O3:Z3) -> 50 | AB3: Pay-as-you-go | AC3: 296.66 | AD3: 13.45 | AE3: 45.05 | AF3: 0.74 | AG3: 18.03 | AH3: 85.42 | AI3: 16.95 | AJ3: 93.67 | AK3: 67.27 | AL3: 26.33 | AM3: 44.8 | AN3: 0.09 | AO3: 708.46
A4: SUB-351850519 | B4: 14259 | C4: 0 | D4: 3545 | E4: 864 | F4: 3502 | G4: 266 | H4: 380 | I4: 1597 | J4: 6096 | K4: 1170 | L4: 1204 | M4: 0 | N4: =SUM(B4:M4) -> 32883 | O4: 6 | P4: 5 | Q4: 1 | R4: 1 | S4: 2 | T4: 6 | U4: 1 | V4: 1 | W4: 6 | X4: 0 | Y4: 4 | Z4: 1 | AA4: =SUM(O4:Z4) -> 34 | AB4: Pay-as-you-go | AC4: 285.72 | AD4: 0.45 | AE4: 70.99 | AF4: 17.37 | AG4: 70.22 | AH4: 5.86 | AI4: 7.69 | AJ4: 32.03 | AK4: 122.46 | AL4: 23.4 | AM4: 24.44 | AN4: 0.09 | AO4: 660.72
A5: SUB-294859069 | B5: 13847 | C5: 785 | D5: 2401 | E5: 4826 | F5: 0 | G5: 5638 | H5: 13354 | I5: 105 | J5: 6021 | K5: 1605 | L5: 26 | M5: 3120 | N5: =SUM(B5:M5) -> 51728 | O5: 2 | P5: 4 | Q5: 7 | R5: 13 | S5: 4 | T5: 7 | U5: 1 | V5: 2 | W5: 4 | X5: 0 | Y5: 2 | Z5: 2 | AA5: =SUM(O5:Z5) -> 48 | AB5: Pay-as-you-go | AC5: 277.12 | AD5: 16.06 | AE5: 48.65 | AF5: 97.69 | AG5: 0.36 | AH5: 113.39 | AI5: 267.17 | AJ5: 2.28 | AK5: 120.78 | AL5: 32.1 | AM5: 0.7 | AN5: 62.58 | AO5: 1038.88
A6: SUB-587875037 | B6: 12851 | C6: 3158 | D6: 2085 | E6: 2386 | F6: 2696 | G6: 2703 | H6: 3225 | I6: 9891 | J6: 2753 | K6: 7190 | L6: 7893 | M6: 2733 | N6: =SUM(B6:M6) -> 59564 | O6: 1 | P6: 4 | Q6: 5 | R6: 2 | S6: 2 | T6: 3 | U6: 5 | V6: 2 | W6: 4 | X6: 3 | Y6: 11 | Z6: 0 | AA6: =SUM(O6:Z6) -> 42 | AB6: Pay-as-you-go | AC6: 257.11 | AD6: 63.52 | AE6: 42.15 | AF6: 47.9 | AG6: 54.1 | AH6: 54.33 | AI6: 64.95 | AJ6: 198 | AK6: 55.42 | AL6: 144.07 | AM6: 158.85 | AN6: 54.66 | AO6: 1195.06
A7: SUB-859230726 | B7: 12111 | C7: 0 | D7: 0 | E7: 0 | F7: 2336 | G7: 1090 | H7: 2941 | I7: 711 | J7: 716 | K7: 4422 | L7: 614 | M7: 6042 | N7: =SUM(B7:M7) -> 30983 | O7: 5 | P7: 9 | Q7: 2 | R7: 9 | S7: 4 | T7: 2 | U7: 3 | V7: 0 | W7: 6 | X7: 7 | Y7: 2 | Z7: 2 | AA7: =SUM(O7:Z7) -> 51 | AB7: Pay-as-you-go | AC7: 242.67 | AD7: 0.81 | AE7: 0.18 | AF7: 0.81 | AG7: 47.08 | AH7: 21.98 | AI7: 59.09 | AJ7: 14.22 | AK7: 14.86 | AL7: 89.07 | AM7: 12.46 | AN7: 121.02 | AO7: 624.25
A8: SUB-489079307 | B8: 11013 | C8: 0 | D8: 5112 | E8: 802 | F8: 7754 | G8: 801 | H8: 0 | I8: 3679 | J8: 1273 | K8: 1031 | L8: 3554 | M8: 6803 | N8: =SUM(B8:M8) -> 41822 | O8: 2 | P8: 0 | Q8: 11 | R8: 7 | S8: 21 | T8: 5 | U8: 10 | V8: 7 | W8: 8 | X8: 5 | Y8: 3 | Z8: 10 | AA8: =SUM(O8:Z8) -> 89 | AB8: Pay-as-you-go | AC8: 220.44 | AD8: 0 | AE8: 103.23 | AF8: 16.67 | AG8: 156.97 | AH8: 16.47 | AI8: 0.9 | AJ8: 74.21 | AK8: 26.18 | AL8: 21.07 | AM8: 71.35 | AN8: 136.96 | AO8: 844.45
A9: SUB-560808878 | B9: 10958 | C9: 394 | D9: 2490 | E9: 820 | F9: 0 | G9: 4804 | H9: 766 | I9: 4820 | J9: 1626 | K9: 1683 | L9: 1153 | M9: 1296 | N9: =SUM(B9:M9) -> 30810 | O9: 4 | P9: 2 | Q9: 2 | R9: 17 | S9: 0 | T9: 1 | U9: 1 | V9: 0 | W9: 1 | X9: 4 | Y9: 12 | Z9: 2 | AA9: =SUM(O9:Z9) -> 46 | AB9: Pay-as-you-go | AC9: 219.52 | AD9: 8.06 | AE9: 49.98 | AF9: 17.93 | AG9: 0 | AH9: 96.17 | AI9: 15.41 | AJ9: 96.4 | AK9: 32.61 | AL9: 34.02 | AM9: 24.14 | AN9: 26.1 | AO9: 620.34
A10: SUB-657328973 | B10: 10167 | C10: 735 | D10: 973 | E10: 3149 | F10: 432 | G10: 0 | H10: 3276 | I10: 1523 | J10: 781 | K10: 2046 | L10: 2119 | M10: 2500 | N10: =SUM(B10:M10) -> 27701 | O10: 4 | P10: 5 | Q10: 3 | R10: 2 | S10: 1 | T10: 1 | U10: 0 | V10: 10 | W10: 1 | X10: 0 | Y10: 3 | Z10: 2 | AA10: =SUM(O10:Z10) -> 32 | AB10: Pay-as-you-go | AC10: 203.7 | AD10: 15.15 | AE10: 19.73 | AF10: 63.16 | AG10: 8.73 | AH10: 0.09 | AI10: 65.52 | AJ10: 31.36 | AK10: 15.71 | AL10: 40.92 | AM10: 42.65 | AN10: 50.18 | AO10: 556.9
A11: SUB-614797073 | B11: 9798 | C11: 8942 | D11: 2577 | E11: 1928 | F11: 3656 | G11: 0 | H11: 1882 | I11: 1553 | J11: 226 | K11: 2986 | L11: 1340 | M11: 120 | N11: =SUM(B11:M11) -> 35008 | O11: 12 | P11: 1 | Q11: 0 | R11: 3 | S11: 0 | T11: 15 | U11: 2 | V11: 6 | W11: 5 | X11: 1 | Y11: 1 | Z11: 5 | AA11: =SUM(O11:Z11) -> 51 | AB11: Pay-as-you-go | AC11: 197.04 | AD11: 178.93 | AE11: 51.54 | AF11: 38.83 | AG11: 73.12 | AH11: 1.35 | AI11: 37.82 | AJ11: 31.6 | AK11: 4.97 | AL11: 59.81 | AM11: 26.89 | AN11: 2.85 | AO11: 704.75
A12: SUB-178252773 | B12: 9090 | C12: 9078 | D12: 8357 | E12: 3729 | F12: 1709 | G12: 802 | H12: 1035 | I12: 987 | J12: 2066 | K12: 18033 | L12: 1889 | M12: 2684 | N12: =SUM(B12:M12) -> 59459 | O12: 3 | P12: 3 | Q12: 3 | R12: 4 | S12: 7 | T12: 2 | U12: 1 | V12: 0 | W12: 3 | X12: 3 | Y12: 2 | Z12: 4 | AA12: =SUM(O12:Z12) -> 35 | AB12: Pay-as-you-go | AC12: 182.07 | AD12: 181.83 | AE12: 167.41 | AF12: 74.94 | AG12: 34.81 | AH12: 16.22 | AI12: 20.79 | AJ12: 19.74 | AK12: 41.59 | AL12: 360.93 | AM12: 37.96 | AN12: 54.04 | AO12: 1192.33
A13: SUB-225496767 | B13: 8801 | C13: 570 | D13: 6692 | E13: 480 | F13: 256 | G13: 1480 | H13: 1780 | I13: 4424 | J13: 1382 | K13: 1909 | L13: 0 | M13: 5974 | N13: =SUM(B13:M13) -> 33748 | O13: 0 | P13: 0 | Q13: 3 | R13: 8 | S13: 1 | T13: 0 | U13: 2 | V13: 8 | W13: 0 | X13: 0 | Y13: 2 | Z13: 5 | AA13: =SUM(O13:Z13) -> 29 | AB13: Pay-as-you-go | AC13: 176.02 | AD13: 11.4 | AE13: 134.11 | AF13: 10.32 | AG13: 5.21 | AH13: 29.6 | AI13: 35.78 | AJ13: 89.2 | AK13: 27.64 | AL13: 38.18 | AM13: 0.18 | AN13: 119.93 | AO13: 677.57
A14: SUB-758908462 | B14: 8374 | C14: 2752 | D14: 3817 | E14: 169 | F14: 5077 | G14: 1656 | H14: 3978 | I14: 5206 | J14: 2688 | K14: 1636 | L14: 1001 | M14: 161 | N14: =SUM(B14:M14) -> 36515 | O14: 4 | P14: 5 | Q14: 13 | R14: 5 | S14: 1 | T14: 3 | U14: 2 | V14: 0 | W14: 5 | X14: 8 | Y14: 6 | Z14: 19 | AA14: =SUM(O14:Z14) -> 71 | AB14: Pay-as-you-go | AC14: 167.84 | AD14: 55.49 | AE14: 77.51 | AF14: 3.83 | AG14: 101.63 | AH14: 33.39 | AI14: 79.74 | AJ14: 104.12 | AK14: 54.21 | AL14: 33.44 | AM14: 20.56 | AN14: 4.93 | AO14: 736.69
... A343: SUB-794177654 | B343: 10 | C343: 3854 | D343: 2170 | E343: 3470 | F343: 4578 | G343: 4564 | H343: 3505 | I343: 3349 | J343: 788 | K343: 887 | L343: 3232 | M343: 2241 | N343: =SUM(B343:M343) -> 32648 | O343: 3 | P343: 3 | Q343: 4 | R343: 4 | S343: 3 | T343: 7 | U343: 5 | V343: 0 | W343: 3 | X343: 6 | Y343: 3 | Z343: 4 | AA343: =SUM(O343:Z343) -> 45 | AB343: Pay-as-you-go | AC343: 0.47 | AD343: 77.35 | AE343: 43.76 | AF343: 69.76 | AG343: 91.83 | AH343: 91.91 | AI343: 70.55 | AJ343: 66.98 | AK343: 16.03 | AL343: 18.28 | AM343: 64.91 | AN343: 45.18 | AO343: 657.01
A344: SUB-928511911 | B344: 0 | C344: 12944 | D344: 6298 | E344: 0 | F344: 28267 | G344: 2922 | H344: 6337 | I344: 217 | J344: 1423 | K344: 4798 | L344: 287 | M344: 2231 | N344: =SUM(B344:M344) -> 65724 | O344: 0 | P344: 4 | Q344: 11 | R344: 5 | S344: 5 | T344: 4 | U344: 2 | V344: 4 | W344: 5 | X344: 2 | Y344: 2 | Z344: 3 | AA344: =SUM(O344:Z344) -> 47 | AB344: Pay-as-you-go | AD344: 259.24 | AE344: 126.95 | AF344: 0.45 | AG344: 565.79 | AH344: 58.8 | AI344: 126.92 | AJ344: 4.7 | AK344: 28.91 | AL344: 96.14 | AM344: 5.92 | AN344: 44.89 | AO344: 1318.71
A345: SUB-414114481 | B345: 0 | C345: 8455 | D345: 10681 | E345: 16876 | F345: 6881 | G345: 612 | H345: 4753 | I345: 517 | J345: 7759 | K345: 1043 | L345: 518 | M345: 8529 | N345: =SUM(B345:M345) -> 66624 | O345: 3 | P345: 17 | Q345: 5 | R345: 1 | S345: 1 | T345: 3 | U345: 0 | V345: 0 | W345: 2 | X345: 3 | Y345: 3 | Z345: 2 | AA345: =SUM(O345:Z345) -> 40 | AB345: Pay-as-you-go | AC345: 0.27 | AD345: 170.63 | AE345: 214.07 | AF345: 337.61 | AG345: 137.71 | AH345: 12.51 | AI345: 95.06 | AJ345: 10.34 | AK345: 155.36 | AL345: 21.13 | AM345: 10.63 | AN345: 170.76 | AO345: 1336.08
A346: SUB-996400695 | B346: 0 | C346: 6784 | D346: 1703 | E346: 1357 | F346: 3225 | G346: 2122 | H346: 3376 | I346: 3244 | J346: 4072 | K346: 6330 | L346: 887 | M346: 1919 | N346: =SUM(B346:M346) -> 35019 | O346: 0 | P346: 1 | Q346: 15 | R346: 1 | S346: 5 | T346: 1 | U346: 7 | V346: 0 | W346: 15 | X346: 2 | Y346: 0 | Z346: 0 | AA346: =SUM(O346:Z346) -> 47 | AB346: Pay-as-you-go | AD346: 135.77 | AE346: 35.41 | AF346: 27.23 | AG346: 64.95 | AH346: 42.53 | AI346: 68.15 | AJ346: 64.88 | AK346: 82.79 | AL346: 126.78 | AM346: 17.74 | AN346: 38.38 | AO346: 704.61
A347: SUB-137805061 | B347: 0 | C347: 5485 | D347: 0 | E347: 1241 | F347: 3883 | G347: 3914 | H347: 5069 | I347: 2805 | J347: 2662 | K347: 8754 | L347: 2346 | M347: 3 | N347: =SUM(B347:M347) -> 36162 | O347: 0 | P347: 1 | Q347: 11 | R347: 2 | S347: 4 | T347: 6 | U347: 1 | V347: 16 | W347: 14 | X347: 3 | Y347: 4 | Z347: 1 | AA347: =SUM(O347:Z347) -> 63 | AB347: Pay-as-you-go | AD347: 109.79 | AE347: 0.99 | AF347: 25 | AG347: 78.02 | AH347: 78.82 | AI347: 101.47 | AJ347: 57.54 | AK347: 54.5 | AL347: 175.35 | AM347: 47.28 | AN347: 0.15 | AO347: 728.91
A348: SUB-474945743 | B348: 0 | C348: 5080 | D348: 3052 | E348: 4642 | F348: 387 | G348: 11216 | H348: 0 | I348: 1681 | J348: 3299 | K348: 0 | L348: 333 | M348: 528 | N348: =SUM(B348:M348) -> 30218 | O348: 7 | P348: 2 | Q348: 4 | R348: 7 | S348: 1 | T348: 14 | U348: 8 | V348: 3 | W348: 2 | X348: 0 | Y348: 2 | Z348: 8 | AA348: =SUM(O348:Z348) -> 58 | AB348: Pay-as-you-go | AC348: 0.63 | AD348: 101.78 | AE348: 61.4 | AF348: 93.47 | AG348: 7.83 | AH348: 225.58 | AI348: 0.72 | AJ348: 33.89 | AK348: 66.16 | AL348: 0 | AM348: 6.84 | AN348: 11.28 | AO348: 609.58
A349: SUB-320112847 | B349: 0 | C349: 5015 | D349: 740 | E349: 3381 | F349: 719 | G349: 2378 | H349: 6413 | I349: 5460 | J349: 909 | K349: 2808 | L349: 2702 | M349: 878 | N349: =SUM(B349:M349) -> 31403 | O349: 1 | P349: 0 | Q349: 3 | R349: 5 | S349: 5 | T349: 0 | U349: 14 | V349: 0 | W349: 2 | X349: 0 | Y349: 4 | Z349: 12 | AA349: =SUM(O349:Z349) -> 46 | AB349: Pay-as-you-go | AC349: 0.09 | AD349: 100.3 | AE349: 15.07 | AF349: 68.07 | AG349: 14.83 | AH349: 47.56 | AI349: 129.52 | AJ349: 109.2 | AK349: 18.36 | AL349: 56.16 | AM349: 54.4 | AN349: 18.64 | AO349: 632.2
A350: SUB-309284306 | B350: 0 | C350: 4805 | D350: 2452 | E350: 0 | F350: 5313 | G350: 4974 | H350: 1410 | I350: 532 | J350: 1429 | K350: 2790 | L350: 7453 | M350: 1636 | N350: =SUM(B350:M350) -> 32794 | O350: 4 | P350: 8 | Q350: 3 | R350: 3 | S350: 5 | T350: 1 | U350: 3 | V350: 7 | W350: 3 | X350: 5 | Y350: 4 | Z350: 0 | AA350: =SUM(O350:Z350) -> 46 | AB350: Pay-as-you-go | AC350: 0.36 | AD350: 96.82 | AE350: 49.31 | AF350: 0.27 | AG350: 106.71 | AH350: 99.57 | AI350: 28.47 | AJ350: 11.27 | AK350: 28.85 | AL350: 56.25 | AM350: 149.42 | AN350: 32.72 | AO350: 660.02
A351: SUB-314510883 | B351: 0 | C351: 4621 | D351: 1887 | E351: 0 | F351: 1445 | G351: 0 | H351: 5515 | I351: 4786 | J351: 7558 | K351: 2456 | L351: 810 | M351: 353 | N351: =SUM(B351:M351) -> 29431 | O351: 2 | P351: 4 | Q351: 5 | R351: 3 | S351: 4 | T351: 0 | U351: 3 | V351: 2 | W351: 13 | X351: 8 | Y351: 13 | Z351: 0 | AA351: =SUM(O351:Z351) -> 57 | AB351: Pay-as-you-go | AC351: 0.18 | AD351: 92.78 | AE351: 38.19 | AF351: 0.27 | AG351: 29.26 | AH351: 0 | AI351: 110.57 | AJ351: 95.9 | AK351: 152.33 | AL351: 49.84 | AM351: 17.37 | AN351: 7.06 | AO351: 593.75
A352: SUB-890910481 | B352: 0 | C352: 4606 | D352: 3329 | E352: 3229 | F352: 1213 | G352: 228 | H352: 5439 | I352: 7127 | J352: 2029 | K352: 927 | L352: 0 | M352: 4876 | N352: =SUM(B352:M352) -> 33003 | O352: 7 | P352: 6 | Q352: 0 | R352: 4 | S352: 3 | T352: 0 | U352: 9 | V352: 0 | W352: 2 | X352: 12 | Y352: 2 | Z352: 17 | AA352: =SUM(O352:Z352) -> 62 | AB352: Pay-as-you-go | AC352: 0.63 | AD352: 92.66 | AE352: 66.58 | AF352: 64.94 | AG352: 24.53 | AH352: 4.56 | AI352: 109.59 | AJ352: 142.54 | AK352: 40.76 | AL352: 19.62 | AM352: 0.18 | AN352: 99.05 | AO352: 665.64
A353: SUB-122771504 | B353: 0 | C353: 3665 | D353: 8412 | E353: 455 | F353: 1634 | G353: 5543 | H353: 1795 | I353: 0 | J353: 1217 | K353: 1437 | L353: 7042 | M353: 2813 | N353: =SUM(B353:M353) -> 34013 | O353: 9 | P353: 3 | Q353: 0 | R353: 2 | S353: 1 | T353: 5 | U353: 2 | V353: 0 | W353: 4 | X353: 1 | Y353: 3 | Z353: 4 | AA353: =SUM(O353:Z353) -> 34 | AB353: Pay-as-you-go | AC353: 0.81 | AD353: 73.57 | AE353: 168.24 | AF353: 9.28 | AG353: 32.77 | AH353: 111.31 | AI353: 36.08 | AJ353: 0 | AK353: 24.7 | AL353: 28.83 | AM353: 141.11 | AN353: 56.62 | AO353: 683.32
A354: SUB-907081959 | B354: 0 | C354: 3663 | D354: 3230 | E354: 7819 | F354: 51 | G354: 1621 | H354: 603 | I354: 11647 | J354: 1331 | K354: 300 | L354: 2455 | M354: 2453 | N354: =SUM(B354:M354) -> 35173 | O354: 9 | P354: 1 | Q354: 5 | R354: 2 | S354: 0 | T354: 10 | U354: 8 | V354: 5 | W354: 9 | X354: 9 | Y354: 5 | Z354: 6 | AA354: =SUM(O354:Z354) -> 69 | AB354: Pay-as-you-go | AC354: 0.81 | AD354: 73.35 | AE354: 65.05 | AF354: 156.56 | AG354: 1.02 | AH354: 33.32 | AI354: 12.78 | AJ354: 233.39 | AK354: 27.43 | AL354: 6.81 | AM354: 49.55 | AN354: 49.6 | AO354: 709.67
A355: SUB-207733458 | B355: 0 | C355: 3423 | D355: 3195 | E355: 926 | F355: 6028 | G355: 148 | H355: 5407 | I355: 794 | J355: 4141 | K355: 994 | L355: 600 | M355: 4855 | N355: =SUM(B355:M355) -> 30511 | O355: 4 | P355: 7 | Q355: 1 | R355: 5 | S355: 5 | T355: 0 | U355: 4 | V355: 6 | W355: 3 | X355: 0 | Y355: 0 | Z355: 2 | AA355: =SUM(O355:Z355) -> 37 | AB355: Pay-as-you-go | AC355: 0.36 | AD355: 69.09 | AE355: 63.99 | AF355: 18.97 | AG355: 121.01 | AH355: 2.96 | AI355: 108.5 | AJ355: 16.42 | AK355: 83.09 | AL355: 19.88 | AM355: 12 | AN355: 97.28 | AO355: 613.55
A356: SUB-742447206 | B356: 0 | C356: 3355 | D356: 2163 | E356: 5882 | F356: 3084 | G356: 6988 | H356: 676 | I356: 3189 | J356: 954 | K356: 1652 | L356: 7814 | M356: 1369 | N356: =SUM(B356:M356) -> 37126 | O356: 7 | P356: 11 | Q356: 3 | R356: 2 | S356: 3 | T356: 9 | U356: 1 | V356: 1 | W356: 8 | X356: 1 | Y356: 5 | Z356: 1 | AA356: =SUM(O356:Z356) -> 52 | AB356: Pay-as-you-go | AC356: 0.63 | AD356: 68.09 | AE356: 43.53 | AF356: 117.82 | AG356: 61.95 | AH356: 140.57 | AI356: 13.61 | AJ356: 63.87 | AK356: 19.8 | AL356: 33.13 | AM356: 156.73 | AN356: 27.47 | AO356: 747.2
A357: SUB-425606111 | B357: 0 | C357: 3179 | D357: 8158 | E357: 490 | F357: 2368 | G357: 5265 | H357: 637 | I357: 0 | J357: 2524 | K357: 5093 | L357: 170 | M357: 6131 | N357: =SUM(B357:M357) -> 34015 | O357: 5 | P357: 7 | Q357: 9 | R357: 7 | S357: 2 | T357: 3 | U357: 3 | V357: 5 | W357: 2 | X357: 4 | Y357: 2 | Z357: 1 | AA357: =SUM(O357:Z357) -> 50 | AB357: Pay-as-you-go | AC357: 0.45 | AD357: 64.21 | AE357: 163.97 | AF357: 10.43 | AG357: 47.54 | AH357: 105.57 | AI357: 13.01 | AJ357: 0.45 | AK357: 50.66 | AL357: 102.22 | AM357: 3.58 | AN357: 122.71 | AO357: 684.8
A358: SUB-545952317 | B358: 0 | C358: 2741 | D358: 2013 | E358: 1935 | F358: 5213 | G358: 1488 | H358: 7324 | I358: 0 | J358: 1774 | K358: 4351 | L358: 2432 | M358: 0 | N358: =SUM(B358:M358) -> 29271 | O358: 10 | P358: 7 | Q358: 7 | R358: 5 | S358: 1 | T358: 5 | U358: 1 | V358: 4 | W358: 0 | X358: 7 | Y358: 0 | Z358: 11 | AA358: =SUM(O358:Z358) -> 58 | AB358: Pay-as-you-go | AC358: 0.9 | AD358: 55.45 | AE358: 40.89 | AF358: 39.15 | AG358: 104.35 | AH358: 30.21 | AI358: 146.57 | AJ358: 0.36 | AK358: 35.48 | AL358: 87.65 | AM358: 48.64 | AN358: 0.99 | AO358: 590.64
A359: SUB-921245657 | B359: 0 | C359: 2501 | D359: 1212 | E359: 2889 | F359: 0 | G359: 3455 | H359: 4243 | I359: 1786 | J359: 1282 | K359: 0 | L359: 382 | M359: 2291 | N359: =SUM(B359:M359) -> 20041 | O359: 12 | P359: 2 | Q359: 15 | R359: 2 | S359: 12 | T359: 1 | U359: 7 | V359: 3 | W359: 4 | X359: 1 | Y359: 6 | Z359: 0 | AA359: =SUM(O359:Z359) -> 65 | AB359: Pay-as-you-go | AC359: 1.08 | AD359: 50.2 | AE359: 25.59 | AF359: 57.96 | AG359: 1.08 | AH359: 69.19 | AI359: 85.49 | AJ359: 35.99 | AK359: 26 | AL359: 0.09 | AM359: 8.18 | AN359: 45.82 | AO359: 406.67
... A377: SUB-940875053 | B377: 0 | C377: 0 | D377: 0 | E377: 1186 | F377: 555 | G377: 1267 | H377: 1049 | I377: 6086 | J377: 7495 | K377: 1373 | L377: 1827 | M377: 10051 | N377: =SUM(B377:M377) -> 30889 | O377: 5 | P377: 6 | Q377: 4 | R377: 5 | S377: 2 | T377: 3 | U377: 5 | V377: 3 | W377: 3 | X377: 2 | Y377: 5 | Z377: 4 | AA377: =SUM(O377:Z377) -> 47 | AB377: Pay-as-you-go | AC377: 0.45 | AD377: 0.54 | AE377: 0.36 | AF377: 24.17 | AG377: 11.28 | AH377: 25.61 | AI377: 21.43 | AJ377: 121.99 | AK377: 150.17 | AL377: 27.64 | AM377: 36.99 | AN377: 201.38 | AO377: 622.01
A378: SUB-538425944 | B378: 0 | C378: 5505 | D378: 2571 | E378: 3232 | F378: 981 | G378: 5090 | H378: 0 | I378: 585 | J378: 4045 | K378: 8118 | L378: 263 | M378: 3654 | N378: =SUM(B378:M378) -> 34044 | O378: 0 | P378: 0 | Q378: 0 | R378: 4 | S378: 2 | T378: 2 | U378: 3 | V378: 2 | W378: 3 | X378: 1 | Y378: 15 | Z378: 4 | AA378: =SUM(O378:Z378) -> 36 | AB378: Pay-as-you-go | AD378: 110.1 | AE378: 51.42 | AF378: 65 | AG378: 19.8 | AH378: 101.98 | AI378: 0.27 | AJ378: 11.88 | AK378: 81.17 | AL378: 162.45 | AM378: 6.61 | AN378: 73.44 | AO378: 684.12
A379: SUB-460053662 | B379: 0 | C379: 5209 | D379: 1338 | E379: 2372 | F379: 2224 | G379: 2952 | H379: 402 | I379: 786 | J379: 3535 | K379: 2501 | L379: 3292 | M379: 3385 | N379: =SUM(B379:M379) -> 27996 | O379: 0 | P379: 1 | Q379: 4 | R379: 1 | S379: 4 | T379: 7 | U379: 1 | V379: 5 | W379: 6 | X379: 0 | Y379: 6 | Z379: 5 | AA379: =SUM(O379:Z379) -> 40 | AB379: Pay-as-you-go | AD379: 104.27 | AE379: 27.12 | AF379: 47.53 | AG379: 44.84 | AH379: 59.67 | AI379: 8.13 | AJ379: 16.17 | AK379: 71.24 | AL379: 50.02 | AM379: 66.38 | AN379: 68.15 | AO379: 563.52
A380: SUB-719844185 | B380: 0 | C380: 5015 | D380: 3216 | E380: 160 | F380: 1129 | G380: 4427 | H380: 596 | I380: 549 | J380: 2368 | K380: 6627 | L380: 1110 | M380: 725 | N380: =SUM(B380:M380) -> 25922 | O380: 0 | P380: 2 | Q380: 2 | R380: 0 | S380: 3 | T380: 7 | U380: 12 | V380: 3 | W380: 4 | X380: 1 | Y380: 4 | Z380: 2 | AA380: =SUM(O380:Z380) -> 40 | AB380: Pay-as-you-go | AD380: 100.48 | AE380: 64.5 | AF380: 3.2 | AG380: 22.85 | AH380: 89.17 | AI380: 13 | AJ380: 11.25 | AK380: 47.72 | AL380: 132.63 | AM380: 22.56 | AN380: 14.68 | AO380: 522.04
A381: SUB-571036263 | B381: 0 | C381: 4181 | D381: 2280 | E381: 1076 | F381: 1524 | G381: 1440 | H381: 662 | I381: 5162 | J381: 4261 | K381: 1781 | L381: 2336 | M381: 1877 | N381: =SUM(B381:M381) -> 26580 | O381: 0 | P381: 1 | Q381: 18 | R381: 1 | S381: 7 | T381: 4 | U381: 5 | V381: 3 | W381: 2 | X381: 10 | Y381: 12 | Z381: 9 | AA381: =SUM(O381:Z381) -> 72 | AB381: Pay-as-you-go | AD381: 83.71 | AE381: 47.22 | AF381: 21.61 | AG381: 31.11 | AH381: 29.16 | AI381: 13.69 | AJ381: 103.51 | AK381: 85.4 | AL381: 36.52 | AM381: 47.8 | AN381: 38.35 | AO381: 538.08
A382: SUB-720331552 | B382: 0 | C382: 3987 | D382: 6239 | E382: 2245 | F382: 1718 | G382: 340 | H382: 5452 | I382: 597 | J382: 2186 | K382: 1057 | L382: 3157 | M382: 4558 | N382: =SUM(B382:M382) -> 31536 | O382: 0 | P382: 9 | Q382: 5 | R382: 9 | S382: 0 | T382: 15 | U382: 5 | V382: 1 | W382: 6 | X382: 1 | Y382: 8 | Z382: 1 | AA382: =SUM(O382:Z382) -> 60 | AB382: Pay-as-you-go | AD382: 80.55 | AE382: 125.23 | AF382: 45.71 | AG382: 34.36 | AH382: 8.15 | AI382: 109.49 | AJ382: 12.03 | AK382: 44.26 | AL382: 21.23 | AM382: 63.86 | AN382: 91.25 | AO382: 636.12
A383: SUB-653039003 | B383: 0 | C383: 3190 | D383: 0 | E383: 113 | F383: 2319 | G383: 983 | H383: 6310 | I383: 1648 | J383: 14311 | K383: 4529 | L383: 0 | M383: 1467 | N383: =SUM(B383:M383) -> 34870 | O383: 0 | P383: 2 | Q383: 2 | R383: 1 | S383: 5 | T383: 3 | U383: 11 | V383: 4 | W383: 20 | X383: 9 | Y383: 1 | Z383: 10 | AA383: =SUM(O383:Z383) -> 68 | AB383: Pay-as-you-go | AD383: 63.98 | AE383: 0.18 | AF383: 2.35 | AG383: 46.83 | AH383: 19.93 | AI383: 127.19 | AJ383: 33.32 | AK383: 288.02 | AL383: 91.39 | AM383: 0.09 | AN383: 30.24 | AO383: 703.52
A384: SUB-975460557 | B384: 0 | C384: 3176 | D384: 3970 | E384: 3243 | F384: 1651 | G384: 883 | H384: 1826 | I384: 1534 | J384: 0 | K384: 6794 | L384: 1679 | M384: 9343 | N384: =SUM(B384:M384) -> 34099 | O384: 0 | P384: 0 | Q384: 10 | R384: 11 | S384: 0 | T384: 1 | U384: 6 | V384: 6 | W384: 2 | X384: 3 | Y384: 4 | Z384: 2 | AA384: =SUM(O384:Z384) -> 45 | AB384: Pay-as-you-go | AD384: 63.52 | AE384: 80.3 | AF384: 65.85 | AG384: 33.02 | AH384: 17.75 | AI384: 37.06 | AJ384: 31.22 | AK384: 0.18 | AL384: 136.15 | AM384: 33.94 | AN384: 187.04 | AO384: 686.03
A385: SUB-212766319 | B385: 0 | C385: 2665 | D385: 3064 | E385: 1877 | F385: 3049 | G385: 705 | H385: 1070 | I385: 2705 | J385: 7948 | K385: 719 | L385: 2940 | M385: 330 | N385: =SUM(B385:M385) -> 27072 | O385: 0 | P385: 0 | Q385: 1 | R385: 0 | S385: 1 | T385: 8 | U385: 0 | V385: 6 | W385: 1 | X385: 9 | Y385: 3 | Z385: 1 | AA385: =SUM(O385:Z385) -> 30 | AB385: Pay-as-you-go | AD385: 53.3 | AE385: 61.37 | AF385: 37.54 | AG385: 61.07 | AH385: 14.82 | AI385: 21.4 | AJ385: 54.64 | AK385: 159.05 | AL385: 15.19 | AM385: 59.07 | AN385: 6.69 | AO385: 544.14
...

Sheet Reduced Tarrif
B1: Data (rounded up to MB) | O1: Talktime (rounded up to mins) | AC1: Billing (in euros)
A2: Customer_ID | B2: January_Data | C2: February_Data | D2: March_Data | E2: April_Data | F2: May_Data | G2: June_Data | H2: July_Data | I2: August_Data | J2: September_Data | K2: October_Data | L2: November_Data | M2: December_Data | N2: Total_Data_Usage | O2: January_Talktime | P2: February_Talktime | Q2: March_Talktime | R2: April_Talktime | S2: May_Talktime | T2: June_Talktime | U2: July_Talktime | V2: August_Talktime | W2: September_Talktime | X2: October_Talktime | Y2: November_Talktime | Z2: December_Talktime | AA2: Total_Talktime | AB2: Plan | AC2: January | AD2: February | AE2: March | AF2: April | AG2: May | AH2: June | AI2: July | AJ2: August | AK2: September | AL2: October | AM2: November | AN2: December | AO2: Total billing amount
A3: SUB-729143503 | B3: 28054 | C3: 2896 | D3: 1352 | E3: 3757 | F3: 224 | G3: 4013 | H3: 9167 | I3: 5242 | J3: 1597 | K3: 962 | L3: 0 | M3: 457 | N3: =SUM(B3:M3) -> 57721 | O3: 0 | P3: 7 | Q3: 2 | R3: 1 | S3: 2 | T3: 6 | U3: 13 | V3: 0 | W3: 10 | X3: 10 | Y3: 11 | Z3: 4 | AA3: =SUM(O3:Z3) -> 66 | AB3: Reduced rate | AC3: 290.53 | AD3: 39.3 | AE3: 23.61 | AF3: 47.61 | AG3: 12.33 | AH3: 50.42 | AI3: 102.31 | AJ3: 62.41 | AK3: 26.46 | AL3: 20.11 | AM3: 10.54 | AN3: 14.76 | AO3: 700.39
A4: SUB-327259441 | B4: 27982 | C4: 418 | D4: 853 | E4: 636 | F4: 664 | G4: 4987 | H4: 1855 | I4: 6696 | J4: 1892 | K4: 888 | L4: 744 | M4: 2698 | N4: =SUM(B4:M4) -> 50313 | O4: 4 | P4: 0 | Q4: 4 | R4: 14 | S4: 3 | T4: 1 | U4: 2 | V4: 1 | W4: 3 | X4: 1 | Y4: 7 | Z4: 2 | AA4: =SUM(O4:Z4) -> 42 | AB4: Reduced rate | AC4: 290.01 | AD4: 14.17 | AE4: 18.72 | AF4: 17.05 | AG4: 16.78 | AH4: 59.91 | AI4: 28.64 | AJ4: 77 | AK4: 29.06 | AL4: 18.92 | AM4: 17.78 | AN4: 37.07 | AO4: 625.11
A5: SUB-720199369 | B5: 24078 | C5: 2041 | D5: 698 | E5: 2977 | F5: 3285 | G5: 0 | H5: 883 | I5: 5063 | J5: 1430 | K5: 472 | L5: 2550 | M5: 348 | N5: =SUM(B5:M5) -> 43825 | O5: 4 | P5: 6 | Q5: 2 | R5: 4 | S5: 3 | T5: 3 | U5: 8 | V5: 0 | W5: 2 | X5: 9 | Y5: 1 | Z5: 5 | AA5: =SUM(O5:Z5) -> 47 | AB5: Reduced rate | AC5: 250.97 | AD5: 30.7 | AE5: 17.07 | AF5: 39.96 | AG5: 42.99 | AH5: 10.14 | AI5: 19.22 | AJ5: 60.62 | AK5: 24.39 | AL5: 15.16 | AM5: 35.54 | AN5: 13.72 | AO5: 560.48
A6: SUB-115774364 | B6: 23075 | C6: 2786 | D6: 285 | E6: 3284 | F6: 7460 | G6: 3169 | H6: 1908 | I6: 340 | J6: 2229 | K6: 2687 | L6: 1171 | M6: 7623 | N6: =SUM(B6:M6) -> 56017 | O6: 2 | P6: 1 | Q6: 5 | R6: 5 | S6: 3 | T6: 7 | U6: 8 | V6: 6 | W6: 0 | X6: 4 | Y6: 4 | Z6: 5 | AA6: =SUM(O6:Z6) -> 50 | AB6: Reduced rate | AC6: 240.84 | AD6: 37.9 | AE6: 13.09 | AF6: 43.08 | AG6: 84.74 | AH6: 42.03 | AI6: 29.47 | AJ6: 13.69 | AK6: 32.28 | AL6: 37.06 | AM6: 21.9 | AN6: 86.47 | AO6: 682.55
A7: SUB-687511952 | B7: 22980 | C7: 2123 | D7: 877 | E7: 5629 | F7: 0 | G7: 1866 | H7: 758 | I7: 9672 | J7: 2998 | K7: 7829 | L7: 1930 | M7: 1643 | N7: =SUM(B7:M7) -> 58305 | O7: 0 | P7: 1 | Q7: 3 | R7: 2 | S7: 2 | T7: 4 | U7: 2 | V7: 2 | W7: 7 | X7: 7 | Y7: 4 | Z7: 9 | AA7: =SUM(O7:Z7) -> 43 | AB7: Reduced rate | AC7: 239.79 | AD7: 31.27 | AE7: 18.91 | AF7: 66.38 | AG7: 10.09 | AH7: 28.85 | AI7: 17.67 | AJ7: 106.81 | AK7: 40.32 | AL7: 88.63 | AM7: 29.49 | AN7: 26.87 | AO7: 705.08
A8: SUB-884111294 | B8: 21173 | C8: 1524 | D8: 1486 | E8: 4194 | F8: 1957 | G8: 1902 | H8: 3120 | I8: 2240 | J8: 5878 | K8: 1649 | L8: 9275 | M8: 6060 | N8: =SUM(B8:M8) -> 60458 | O8: 4 | P8: 3 | Q8: 9 | R8: 9 | S8: 0 | T8: 8 | U8: 3 | V8: 19 | W8: 2 | X8: 19 | Y8: 5 | Z8: 2 | AA8: =SUM(O8:Z8) -> 83 | AB8: Reduced rate | AC8: 221.92 | AD8: 25.38 | AE8: 25.3 | AF8: 52.38 | AG8: 29.56 | AH8: 29.41 | AI8: 41.34 | AJ8: 33.34 | AK8: 68.87 | AL8: 27.43 | AM8: 102.99 | AN8: 70.69 | AO8: 728.61
A9: SUB-754009185 | B9: 17678 | C9: 4762 | D9: 3059 | E9: 9400 | F9: 8676 | G9: 5735 | H9: 3588 | I9: 3565 | J9: 1241 | K9: 156 | L9: 2066 | M9: 2313 | N9: =SUM(B9:M9) -> 62239 | O9: 5 | P9: 4 | Q9: 5 | R9: 6 | S9: 4 | T9: 1 | U9: 3 | V9: 5 | W9: 1 | X9: 2 | Y9: 2 | Z9: 3 | AA9: =SUM(O9:Z9) -> 41 | AB9: Reduced rate | AC9: 187.02 | AD9: 57.81 | AE9: 40.83 | AF9: 104.29 | AG9: 96.95 | AH9: 67.39 | AI9: 46.02 | AJ9: 45.89 | AK9: 22.45 | AL9: 11.65 | AM9: 30.75 | AN9: 33.27 | AO9: 744.32
A10: SUB-907933772 | B10: 17563 | C10: 1589 | D10: 1874 | E10: 12192 | F10: 3105 | G10: 1560 | H10: 4199 | I10: 256 | J10: 1707 | K10: 507 | L10: 318 | M10: 0 | N10: =SUM(B10:M10) -> 44870 | O10: 0 | P10: 1 | Q10: 4 | R10: 4 | S10: 10 | T10: 3 | U10: 12 | V10: 1 | W10: 0 | X10: 0 | Y10: 0 | Z10: 3 | AA10: =SUM(O10:Z10) -> 38 | AB10: Reduced rate | AC10: 185.62 | AD10: 25.93 | AE10: 28.93 | AF10: 132.11 | AG10: 41.54 | AH10: 25.74 | AI10: 52.58 | AJ10: 12.6 | AK10: 27.06 | AL10: 15.06 | AM10: 13.17 | AN10: 10.14 | AO10: 570.48
A11: SUB-219686190 | B11: 17311 | C11: 1601 | D11: 4072 | E11: 809 | F11: 209 | G11: 6818 | H11: 1512 | I11: 1615 | J11: 1724 | K11: 11609 | L11: 0 | M11: 5664 | N11: =SUM(B11:M11) -> 52944 | O11: 1 | P11: 2 | Q11: 6 | R11: 6 | S11: 2 | T11: 0 | U11: 3 | V11: 3 | W11: 11 | X11: 5 | Y11: 1 | Z11: 4 | AA11: =SUM(O11:Z11) -> 44 | AB11: Reduced rate | AC11: 183.15 | AD11: 26.1 | AE11: 51.01 | AF11: 18.38 | AG11: 12.18 | AH11: 78.17 | AI11: 25.26 | AJ11: 26.29 | AK11: 27.78 | AL11: 126.33 | AM11: 10.04 | AN11: 66.83 | AO11: 651.52
A12: SUB-275406642 | B12: 16753 | C12: 6127 | D12: 2973 | E12: 4474 | F12: 5775 | G12: 2389 | H12: 6407 | I12: 1415 | J12: 1244 | K12: 2318 | L12: 4557 | M12: 4307 | N12: =SUM(B12:M12) -> 58739 | O12: 7 | P12: 1 | Q12: 6 | R12: 4 | S12: 12 | T12: 1 | U12: 3 | V12: 10 | W12: 1 | X12: 13 | Y12: 4 | Z12: 2 | AA12: =SUM(O12:Z12) -> 64 | AB12: Reduced rate | AC12: 177.87 | AD12: 71.31 | AE12: 40.02 | AF12: 54.93 | AG12: 68.34 | AH12: 33.93 | AI12: 74.21 | AJ12: 24.64 | AK12: 22.48 | AL12: 33.82 | AM12: 55.76 | AN12: 53.16 | AO12: 710.47
A13: SUB-475178203 | B13: 16235 | C13: 3935 | D13: 5728 | E13: 0 | F13: 7943 | G13: 11274 | H13: 2246 | I13: 5507 | J13: 2620 | K13: 632 | L13: 6970 | M13: 3443 | N13: =SUM(B13:M13) -> 66533 | O13: 1 | P13: 4 | Q13: 0 | R13: 11 | S13: 7 | T13: 6 | U13: 2 | V13: 8 | W13: 8 | X13: 6 | Y13: 2 | Z13: 5 | AA13: =SUM(O13:Z13) -> 60 | AB13: Reduced rate | AC13: 172.39 | AD13: 49.54 | AE13: 67.27 | AF13: 10.54 | AG13: 89.77 | AH13: 123.03 | AI13: 32.55 | AJ13: 65.46 | AK13: 36.59 | AL13: 16.61 | AM13: 79.79 | AN13: 44.67 | AO13: 788.21
A14: SUB-384428935 | B14: 16202 | C14: 1977 | D14: 1335 | E14: 6881 | F14: 2099 | G14: 1614 | H14: 1942 | I14: 3511 | J14: 0 | K14: 1531 | L14: 2423 | M14: 1135 | N14: =SUM(B14:M14) -> 40650 | O14: 3 | P14: 21 | Q14: 0 | R14: 3 | S14: 12 | T14: 1 | U14: 15 | V14: 12 | W14: 9 | X14: 3 | Y14: 6 | Z14: 7 | AA14: =SUM(O14:Z14) -> 92 | AB14: Reduced rate | AC14: 172.16 | AD14: 30.81 | AE14: 23.34 | AF14: 78.95 | AG14: 31.58 | AH14: 26.18 | AI14: 30.16 | AJ14: 45.7 | AK14: 10.44 | AL14: 25.45 | AM14: 34.52 | AN14: 21.69 | AO14: 530.98
... A595: SUB-954126260 | B595: 0 | C595: 0 | D595: 4652 | E595: 4346 | F595: 10326 | G595: 1718 | H595: 6680 | I595: 8285 | J595: 3295 | K595: 4550 | L595: 1444 | M595: 1416 | N595: =SUM(B595:M595) -> 46712 | O595: 0 | P595: 0 | Q595: 0 | R595: 3 | S595: 1 | T595: 17 | U595: 2 | V595: 8 | W595: 3 | X595: 5 | Y595: 4 | Z595: 3 | AA595: =SUM(O595:Z595) -> 46 | AB595: Reduced rate | AC595: 9.99 | AD595: 9.99 | AE595: 56.51 | AF595: 53.6 | AG595: 113.3 | AH595: 28.02 | AI595: 76.89 | AJ595: 93.24 | AK595: 43.09 | AL595: 55.74 | AM595: 24.63 | AN595: 24.3 | AO595: 589.3

Sheet Revenue Analysis
A1: Total Revenue | B1: =SUM(Combined_Data!AO3:AO1002) -> 629316.31
A2: Total Revenue Pay as you go | B2: =SUM('Pay as you go'!AO3:AO409) -> 270951.38
A3: Total Revenue Reduced rate | B3: =SUM('Reduced Tarrif'!AO3:AO595) -> 358364.93
A6: Pay as you go Revenue | B6: =SUM('Pay as you go'!AO3:AO409) -> 270951.38
A7: Total Revenue from data | B7: =SUM('Pay as you go'!N3:N409)*0.02 -> 269052.56
A8: Total Revenue from talktime | B8: =SUM('Pay as you go'!AA3:AA409)*0.09 -> 1898.82
A11: Reduced Tarrif Revenue | B11: =SUM('Reduced Tarrif'!AO3:AO595) -> 358364.93
A12: Total Revenue from data | B12: =SUM('Reduced Tarrif'!N3:N595)*0.01 -> 285677.14
A13: Total Revenue from talktime | B13: =SUM('Reduced Tarrif'!AA3:AA595)*0.05 -> 1598.95
A15: Total revenue from data | B15: =SUM(B7,B12) -> 554729.7 | C15: =B15/B1 -> 0.88147993 | D15: of total revenue
A16: Total Revenue from calling | B16: =SUM(B8,B13) -> 3497.77 | C16: =B16/B1 -> 0.0055580476 | D16: of total revenue
A18: Impact of 9.99 monthly rate for the reduced tarrif on revenue | D18: =B1-B15-B16 -> 71088.84 | E18: =D18/B1 -> 0.11296202

Sheet Statistical Analysis
A1: Customer_ID | B1: January | C1: February | D1: March | E1: April | F1: May | G1: June | H1: July | I1: August | J1: September | K1: October | L1: November | M1: December | N1: Total cost Median | AE1: Alle Einnahmen
A2: SUB-729143503 | B2: 290.53 | C2: 39.3 | D2: 23.61 | E2: 47.61 | F2: 12.33 | G2: 50.42 | H2: 102.31 | I2: 62.41 | J2: 26.46 | K2: 20.11 | L2: 10.54 | M2: 14.76 | N2: =MEDIAN(B2:M2) -> 32.88 | AE2: 290.53
A3: SUB-327259441 | B3: 290.01 | C3: 14.17 | D3: 18.72 | E3: 17.05 | F3: 16.78 | G3: 59.91 | H3: 28.64 | I3: 77 | J3: 29.06 | K3: 18.92 | L3: 17.78 | M3: 37.07 | N3: =MEDIAN(B3:M3) -> 23.78 | AE3: 290.01
A4: SUB-720199369 | B4: 250.97 | C4: 30.7 | D4: 17.07 | E4: 39.96 | F4: 42.99 | G4: 10.14 | H4: 19.22 | I4: 60.62 | J4: 24.39 | K4: 15.16 | L4: 35.54 | M4: 13.72 | N4: =MEDIAN(B4:M4) -> 27.545 | AE4: 250.97
A5: SUB-115774364 | B5: 240.84 | C5: 37.9 | D5: 13.09 | E5: 43.08 | F5: 84.74 | G5: 42.03 | H5: 29.47 | I5: 13.69 | J5: 32.28 | K5: 37.06 | L5: 21.9 | M5: 86.47 | N5: =MEDIAN(B5:M5) -> 37.48 | AE5: 240.84
A6: SUB-687511952 | B6: 239.79 | C6: 31.27 | D6: 18.91 | E6: 66.38 | F6: 10.09 | G6: 28.85 | H6: 17.67 | I6: 106.81 | J6: 40.32 | K6: 88.63 | L6: 29.49 | M6: 26.87 | N6: =MEDIAN(B6:M6) -> 30.38 | AE6: 239.79
A7: SUB-884111294 | B7: 221.92 | C7: 25.38 | D7: 25.3 | E7: 52.38 | F7: 29.56 | G7: 29.41 | H7: 41.34 | I7: 33.34 | J7: 68.87 | K7: 27.43 | L7: 102.99 | M7: 70.69 | N7: =MEDIAN(B7:M7) -> 37.34 | AE7: 221.92
A8: SUB-754009185 | B8: 187.02 | C8: 57.81 | D8: 40.83 | E8: 104.29 | F8: 96.95 | G8: 67.39 | H8: 46.02 | I8: 45.89 | J8: 22.45 | K8: 11.65 | L8: 30.75 | M8: 33.27 | N8: =MEDIAN(B8:M8) -> 45.955 | AE8: 187.02
A9: SUB-907933772 | B9: 185.62 | C9: 25.93 | D9: 28.93 | E9: 132.11 | F9: 41.54 | G9: 25.74 | H9: 52.58 | I9: 12.6 | J9: 27.06 | K9: 15.06 | L9: 13.17 | M9: 10.14 | N9: =MEDIAN(B9:M9) -> 26.495 | AE9: 185.62
